Workbook
Name اسم_المؤسسة: 'الإعدادات'!$B$5
Name السجل_التجاري: 'الإعدادات'!$B$6
Name السنة_المالية: 'الإعدادات'!$B$7
Name العملة: 'الإعدادات'!$B$8
Name مسؤول_الموارد_البشرية: 'الإعدادات'!$B$9
Name شعار_المؤسسة: 'الإعدادات'!$B$10
Name بداية_الدوام: 'الإعدادات'!$B$12
Name نهاية_الدوام: 'الإعدادات'!$B$13
Name مدة_الاستراحة: 'الإعدادات'!$B$14
Name ساعات_العمل_المطلوبة: 'الإعدادات'!$B$15
Name دقائق_السماح: 'الإعدادات'!$B$16
Name احتساب_التأخير: 'الإعدادات'!$B$17
Name احتساب_العمل_الإضافي: 'الإعدادات'!$B$18
Name حد_العمل_الإضافي_دقيقة: 'الإعدادات'!$B$19
Name معامل_العمل_الإضافي: 'الإعدادات'!$B$20
Name تفعيل_الدوام_الليلي: 'الإعدادات'!$B$21
Name تفعيل_الدوام_المرن: 'الإعدادات'!$B$22
Name بداية_الدوام_المرن: 'الإعدادات'!$B$23
Name نهاية_الدوام_المرن: 'الإعدادات'!$B$24
Name أيام_العمل_الأسبوعية: 'الإعدادات'!$B$25
Name تنبيه_انتهاء_العقد: 'الإعدادات'!$B$27
Name تنبيه_وثيقة_90: 'الإعدادات'!$B$28
Name تنبيه_وثيقة_30: 'الإعدادات'!$B$29
Name تنبيه_وثيقة_7: 'الإعدادات'!$B$30
Name فترة_الموظف_الجديد: 'الإعدادات'!$B$31
Name الرصيد_السنوي: 'الإعدادات'!$B$33
Name معدل_الاستحقاق_الشهري: 'الإعدادات'!$B$34
Name السماح_بالرصيد_السالب: 'الإعدادات'!$B$35
Name بداية_احتساب_الرصيد: 'الإعدادات'!$B$36
Name الحد_الأقصى_الإجازة_المتصلة: 'الإعدادات'!$B$37
Name أيام_العمل_الشهرية: 'الإعدادات'!$B$39
Name احتساب_خصم_الغياب: 'الإعدادات'!$B$40
Name ساعات_الخصم_اليومية: 'الإعدادات'!$B$41
Name بادئة_الرقم_الوظيفي: 'الإعدادات'!$B$42
Name احتياطي_تسوية: 'الإعدادات'!$B$43
Name وزن_جودة_العمل: 'الإعدادات'!$B$45
Name وزن_الالتزام: 'الإعدادات'!$B$46
Name وزن_الإنتاجية: 'الإعدادات'!$B$47
Name وزن_التعاون: 'الإعدادات'!$B$48
Name وزن_الأهداف: 'الإعدادات'!$B$49
Name مجموع_الأوزان: 'الإعدادات'!$B$50
Name تقرير_الشهر: 'الإعدادات'!$B$52
Name تقرير_السنة: 'الإعدادات'!$B$53
Name قائمة_الإدارات: 'الإعدادات'!$H$5:$H$64
Name قائمة_الأقسام: 'الإعدادات'!$I$5:$I$64
Name قائمة_المسميات: 'الإعدادات'!$J$5:$J$64
Name قائمة_أنواع_التوظيف: 'الإعدادات'!$K$5:$K$64
Name قائمة_حالات_الموظف: 'الإعدادات'!$L$5:$L$64
Name قائمة_أنواع_الإجازات: 'الإعدادات'!$M$5:$M$64
Name قائمة_حالات_الطلب: 'الإعدادات'!$N$5:$N$64
Name قائمة_حالات_الحضور: 'الإعدادات'!$O$5:$O$64
Name قائمة_أيام_الأسبوع: 'الإعدادات'!$P$5:$P$64
Name قائمة_أنواع_الوثائق: 'الإعدادات'!$Q$5:$Q$64
Name قائمة_أنواع_البدلات: 'الإعدادات'!$R$5:$R$64
Name قائمة_أنواع_الخصومات: 'الإعدادات'!$S$5:$S$64
Name قائمة_حالات_التوظيف: 'الإعدادات'!$T$5:$T$64
Name قائمة_حالات_القرار: 'الإعدادات'!$U$5:$U$64
Name قائمة_أنواع_الجزاءات: 'الإعدادات'!$V$5:$V$64
Name قائمة_أنواع_المكافآت: 'الإعدادات'!$W$5:$W$64
Name قائمة_حالات_العهدة: 'الإعدادات'!$X$5:$X$64

Sheet دليل الاستخدام
A1: دليل استخدام النظام — اقرأ هذا أولًا
A3: تعليمات عامة
B4: • الملف يعمل بدون ماكرو (VBA). جميع الحسابات بمعادلات Excel العادية.
B5: • كل القوائم المنسدلة والحدود الزمنية تُدار من ورقة (الإعدادات). عدّل القيم هناك فقط.
B6: • خلايا الإدخال ملوّنة بالأصفر الفاتح، وخلايا الحساب ملوّنة بالأزرق الفاتح ومحمية من التعديل.
B7: • لإضافة موظف جديد: أدخل صفًا جديدًا في ورقة (الموظفون) مع رقم وظيفي فريد.
B8: • تظهر الموظفين الجدد تلقائيًا في القوائم المنسدلة والتقارير ولوحة التحكم.
B9: • لإضافة قيم جديدة للقوائم: أضفها أسفل العمود المناسب في ورقة (الإعدادات).
B10: • الأوراق محمية بكلمة مرور افتراضية: hr2026 (يمكن تغييرها من مراجعة > إلغاء حماية الورقة).
B11: • الحماية هنا تمنع التعديل العرضي فقط، وليست نظام صلاحيات آمنًا. لا تشارك بيانات الرواتب والملفات الشخصية عبر ملف مفتوح للجميع.
A13: لوحة التحكم
B14: • تعرض مؤشرات القوى العاملة والمؤشرات المالية والتنبيهات الذكية و4 رسوم بيانية.
B15: • تتحدث تلقائيًا عند تعديل بيانات الموظفين أو الرواتب أو الوثائق.
B16: • كل الأرقام محسوبة بمعادلات، ولا تُدخل يدويًا.
A18: الموظفون
B19: • قاعدة البيانات الرئيسية. المعرف الفريد هو (الرقم الوظيفي) في العمود A.
B20: • أدخل الجنس، المؤهل، التخصص، المسمى، الإدارة، القسم، المدير، نوع التوظيف، تواريخ التعيين والعقد، الحالة، الراتب الأساسي والبدلات.
B21: • العمودان (فحص اكتمال البيانات) و(أيام لانتهاء العقد) و(مدة الخدمة) محسوبة تلقائيًا.
B22: • يمنع النظام تكرار الرقم الوظيفي عبر تحقق مخصص، وينبّه عند نقص البيانات الأساسية.
B23: • ملاحظة خصوصية: بيانات الهاتف والحساب البنكي وجهة الطوارئ تُعد حساسة. لا تُتاح لكل من يفتح الملف.
A25: الحضور
B26: • أدخل الرقم الوظيفي والتاريخ ووقت الحضور والانصراف وحالة الدوام.
B27: • يُسترجع اسم الموظف ويوم الأسبوع وأوقات الدوام تلقائيًا من الإعدادات.
B28: • تُحتسب ساعات العمل والتأخير والانصراف المبكر والإضافي تلقائيًا.
B29: • الدوام الليلي: أدخل وقت الانصراف بعد منتصف الليل ويُحتسب الفرق عبر MOD.
B30: • التأخير لا يُحتسب في الإجازات والعطلات والمأموريات (فقط حالتا حاضر/دوام جزئي).
A32: الإجازات
B33: • أدخل الرقم الوظيفي ونوع الإجازة وتاريخي البداية والنهاية وحالة الطلب والمعتمد.
B34: • عدد الأيام والرصيد قبل/بعد محسوبان تلقائيًا.
B35: • لا تُخصم الإجازة من الرصيد إلا عند اعتماد الطلب (حالة = معتمد).
B36: • الرصيد السنوي ومعدل الاستحقاق قابلان للتعديل من الإعدادات.
A38: الرواتب
B39: • أدخل الشهر والسنة والرقم الوظيفي، ثم مكوّنات البدلات والمكافآت والإضافي والخصومات.
B40: • الراتب الأساسي واسم الموظف والإدارة والقسم تُسترجع تلقائيًا من ورقة الموظفين.
B41: • إجمالي الاستحقاقات والخصومات وصافي الراتب محسوبة تلقائيًا.
B42: • عند خصم قسط سلفة أدخل (رقم السلفة) لربط القسط بالسلفة ومنع الخصم المزدوج.
B43: • عمود (تحقق) ينبّه عند تكرار راتب الموظف لنفس الشهر والسنة.
B44: • لا يفترض النظام ضرائب أو تأمينات؛ أي استقطاع قانوني يُدخل يدويًا حسب الدولة واللوائح.
A46: السلف
B47: • أدخل رقم السلفة والموظف والمبلغ وعدد الأقساط. قيمة القسط تُحسب تلقائيًا.
...

Sheet لوحة التحكم
A1: لوحة التحكم الرئيسية — نظام إدارة الموارد البشرية
B2: =اسم_المؤسسة | H2: ="تاريخ التحديث: "&TEXT(TODAY(),"yyyy-mm-dd")
B4: مؤشرات القوى العاملة
B5: إجمالي الموظفين | D5: الموظفون النشطون | F5: الموظفون الموقوفون | H5: الموظفون المعلقون
B6: =COUNTA(الموظفون_الرقم) | D6: =COUNTIF(الموظفون_الحالة,"نشط") | F6: =COUNTIF(الموظفون_الحالة,"موقوف") | H6: =COUNTIF(الموظفون_الحالة,"معلق")
B7: الموظفون في إجازة | D7: الموظفون الجدد (آخر فترة) | F7: انتهت عقودهم | H7: عقود تنتهي خلال 30 يومًا
B8: =COUNTIF(الموظفون_الحالة,"في إجازة") | D8: =COUNTIFS(الموظفون_التعيين,">="&TODAY()-فترة_الموظف_الجديد,الموظفون_الرقم,"<>") | F8: =SUMPRODUCT(ISNUMBER(الموظفون_نهاية_العقد)*(الموظفون_نهاية_العقد<TODAY())) | H8: =SUMPRODUCT(ISNUMBER(الموظفون_نهاية_العقد)*(الموظفون_نهاية_العقد>=TODAY())*(الموظفون_نهاية_العقد<=TODAY()+تنبيه_انتهاء_العقد))
B9: وثائق تنتهي خلال 30 يومًا | D9: وثائق منتهية | F9: متغيبون (في سجل الحضور) | H9: إجمالي حالات التأخير
B10: =COUNTIFS(الوثائق_ايام,">="&0,الوثائق_ايام,"<="&تنبيه_وثيقة_30) | D10: =COUNTIF(الوثائق_ايام,"<0") | F10: =COUNTIF(الحضور_الحالة,"غائب") | H10: =COUNTIF(الحضور_التأخير,">0")
B12: المؤشرات المالية (من كشوف الرواتب)
B13: إجمالي الرواتب الأساسية | D13: إجمالي البدلات | F13: إجمالي المكافآت | H13: إجمالي الاستحقاقات
B14: =SUM(الرواتب_الاساسي) | D14: =SUM(الرواتب_بدل_النقل)+SUM(الرواتب_بدل_السكن)+SUM(الرواتب_بدلات_اخرى) | F14: =SUM(الرواتب_المكافآت) | H14: =SUM(الرواتب_الاستحقاقات)
B15: إجمالي الخصومات | D15: إجمالي صافي الرواتب | F15: إجمالي السلف المتبقية | H15: قيمة العمل الإضافي
B16: =SUM(الرواتب_الخصومات) | D16: =SUM(الرواتب_الصافي) | F16: =SUM(السلف_المتبقي) | H16: =SUM(الرواتب_الاضافي)
B18: التنبيهات الذكية
B19: =IF(COUNTIFS(الوثائق_ايام,"<0")>0,"⚠ يوجد "&COUNTIFS(الوثائق_ايام,"<0")&" وثيقة منتهية","✓ لا وثائق منتهية")
B20: =IF(COUNTIFS(الوثائق_ايام,">="&0,الوثائق_ايام,"<="&تنبيه_وثيقة_7)>0,"⚠ "&COUNTIFS(الوثائق_ايام,">="&0,الوثائق_ايام,"<="&تنبيه_وثيقة_7)&" وثيقة تنتهي خلال 7 أيام","✓ لا وثائق حرجة")
B21: =IF(SUMPRODUCT(ISNUMBER(الموظفون_نهاية_العقد)*(الموظفون_نهاية_العقد>=TODAY())*(الموظفون_نهاية_العقد<=TODAY()+تنبيه_انتهاء_العقد))>0,"⚠ "&SUMPRODUCT(ISNUMBER(الموظفون_نهاية_العقد)*(الموظفون_نهاية_العقد>=TODAY())*(الموظفون_نهاية_العقد<=TODAY()+تنبيه_انتهاء_العقد))&" عقد ينتهي خلال 30 يومًا","✓ لا عقود قريبة الانتهاء")
B22: =IF(SUMPRODUCT((الرواتب_الرقم<>"")*(الرواتب_التحقق="⚠ مكرر"))>0,"⚠ يوجد راتب مكرر لنفس الموظف والشهر","✓ لا تكرار في كشوف الرواتب")
B23: =IF(COUNTIFS(العهد_الحالة,"مسلمة")>0,"⚠ "&COUNTIFS(العهد_الحالة,"مسلمة")&" عهدة لم تُسترجَع بعد","✓ لا عهد معلقة")
B24: =IF(SUMPRODUCT((الموظفون_الاكتمال="⚠ بيانات ناقصة")*1)>0,"⚠ "&SUMPRODUCT((الموظفون_الاكتمال="⚠ بيانات ناقصة")*1)&" موظف ببيانات ناقصة","✓ بيانات الموظفين مكتملة")
B25: =IF(COUNTIF(السلف_المتبقي,">0")>0,"⚠ "&COUNTIF(السلف_المتبقي,">0")&" سلفة قائمة لم تُسدد بالكامل","✓ لا سلف قائمة")
B28: الرسوم البيانية

Sheet الموظفون
A1: الموظفون — نموذج إدخال
A2: الرقم الوظيفي | B2: الاسم الكامل | C2: الجنس | D2: تاريخ الميلاد | E2: رقم الهاتف | F2: البريد الإلكتروني | G2: العنوان | H2: المؤهل العلمي | I2: التخصص | J2: المسمى الوظيفي | K2: الإدارة | L2: القسم | M2: المدير المباشر | N2: نوع التوظيف | O2: تاريخ التعيين | P2: تاريخ بداية العقد | Q2: تاريخ نهاية العقد | R2: الحالة الوظيفية | S2: الراتب الأساسي | T2: البدلات الثابتة | U2: رقم الحساب البنكي | V2: جهة الاتصال للطوارئ | W2: هاتف الطوارئ | X2: رابط الصورة | Y2: رصيد الإجازات الافتتاحي | Z2: ملاحظات إدارية | AA2: فحص اكتمال البيانات | AB2: أيام لانتهاء العقد | AC2: مدة الخدمة (سنة)
AA3: =IF($A3="","",IF(OR($B3="",$E3="",$K3="",$O3="",$S3=""),"⚠ بيانات ناقصة","مكتمل")) | AB3: =IF(OR($A3="",$Q3=""),"",$Q3-TODAY()) | AC3: =IF(OR($A3="",$O3=""),"",IFERROR(YEARFRAC($O3,TODAY(),1),"")
AA4: =IF($A4="","",IF(OR($B4="",$E4="",$K4="",$O4="",$S4=""),"⚠ بيانات ناقصة","مكتمل")) | AB4: =IF(OR($A4="",$Q4=""),"",$Q4-TODAY()) | AC4: =IF(OR($A4="",$O4=""),"",IFERROR(YEARFRAC($O4,TODAY(),1),"")
AA5: =IF($A5="","",IF(OR($B5="",$E5="",$K5="",$O5="",$S5=""),"⚠ بيانات ناقصة","مكتمل")) | AB5: =IF(OR($A5="",$Q5=""),"",$Q5-TODAY()) | AC5: =IF(OR($A5="",$O5=""),"",IFERROR(YEARFRAC($O5,TODAY(),1),"")
AA6: =IF($A6="","",IF(OR($B6="",$E6="",$K6="",$O6="",$S6=""),"⚠ بيانات ناقصة","مكتمل")) | AB6: =IF(OR($A6="",$Q6=""),"",$Q6-TODAY()) | AC6: =IF(OR($A6="",$O6=""),"",IFERROR(YEARFRAC($O6,TODAY(),1),"")
AA7: =IF($A7="","",IF(OR($B7="",$E7="",$K7="",$O7="",$S7=""),"⚠ بيانات ناقصة","مكتمل")) | AB7: =IF(OR($A7="",$Q7=""),"",$Q7-TODAY()) | AC7: =IF(OR($A7="",$O7=""),"",IFERROR(YEARFRAC($O7,TODAY(),1),"")
AA8: =IF($A8="","",IF(OR($B8="",$E8="",$K8="",$O8="",$S8=""),"⚠ بيانات ناقصة","مكتمل")) | AB8: =IF(OR($A8="",$Q8=""),"",$Q8-TODAY()) | AC8: =IF(OR($A8="",$O8=""),"",IFERROR(YEARFRAC($O8,TODAY(),1),"")
AA9: =IF($A9="","",IF(OR($B9="",$E9="",$K9="",$O9="",$S9=""),"⚠ بيانات ناقصة","مكتمل")) | AB9: =IF(OR($A9="",$Q9=""),"",$Q9-TODAY()) | AC9: =IF(OR($A9="",$O9=""),"",IFERROR(YEARFRAC($O9,TODAY(),1),"")
AA10: =IF($A10="","",IF(OR($B10="",$E10="",$K10="",$O10="",$S10=""),"⚠ بيانات ناقصة","مكتمل")) | AB10: =IF(OR($A10="",$Q10=""),"",$Q10-TODAY()) | AC10: =IF(OR($A10="",$O10=""),"",IFERROR(YEARFRAC($O10,TODAY(),1),"")
AA11: =IF($A11="","",IF(OR($B11="",$E11="",$K11="",$O11="",$S11=""),"⚠ بيانات ناقصة","مكتمل")) | AB11: =IF(OR($A11="",$Q11=""),"",$Q11-TODAY()) | AC11: =IF(OR($A11="",$O11=""),"",IFERROR(YEARFRAC($O11,TODAY(),1),"")
AA12: =IF($A12="","",IF(OR($B12="",$E12="",$K12="",$O12="",$S12=""),"⚠ بيانات ناقصة","مكتمل")) | AB12: =IF(OR($A12="",$Q12=""),"",$Q12-TODAY()) | AC12: =IF(OR($A12="",$O12=""),"",IFERROR(YEARFRAC($O12,TODAY(),1),"")
AA13: =IF($A13="","",IF(OR($B13="",$E13="",$K13="",$O13="",$S13=""),"⚠ بيانات ناقصة","مكتمل")) | AB13: =IF(OR($A13="",$Q13=""),"",$Q13-TODAY()) | AC13: =IF(OR($A13="",$O13=""),"",IFERROR(YEARFRAC($O13,TODAY(),1),"")
AA14: =IF($A14="","",IF(OR($B14="",$E14="",$K14="",$O14="",$S14=""),"⚠ بيانات ناقصة","مكتمل")) | AB14: =IF(OR($A14="",$Q14=""),"",$Q14-TODAY()) | AC14: =IF(OR($A14="",$O14=""),"",IFERROR(YEARFRAC($O14,TODAY(),1),"")
... AA502: =IF($A502="","",IF(OR($B502="",$E502="",$K502="",$O502="",$S502=""),"⚠ بيانات ناقصة","مكتمل")) | AB502: =IF(OR($A502="",$Q502=""),"",$Q502-TODAY()) | AC502: =IF(OR($A502="",$O502=""),"",IFERROR(YEARFRAC($O502,TODAY(),1),"")

Sheet الحضور
A1: الحضور — نموذج إدخال
A2: الرقم الوظيفي | B2: اسم الموظف | C2: التاريخ | D2: يوم الأسبوع | E2: وقت الحضور | F2: وقت الانصراف | G2: بداية الدوام الرسمي | H2: نهاية الدوام الرسمي | I2: مدة الاستراحة (ساعة) | J2: ساعات العمل الفعلية | K2: ساعات التأخير | L2: ساعات الانصراف المبكر | M2: ساعات العمل الإضافي | N2: حالة الدوام | O2: الملاحظات
B3: =IFERROR(INDEX(الموظفون_الاسم,MATCH($A3,الموظفون_الرقم,0)),"") | D3: =IF($C3="","",IFERROR(INDEX(قائمة_أيام_الأسبوع,WEEKDAY($C3,1)),"")) | G3: =IF($A3="","",بداية_الدوام) | H3: =IF($A3="","",نهاية_الدوام) | I3: =IF($A3="","",مدة_الاستراحة/60) | J3: =IF(OR($A3="",$E3="",$F3=""),"",IF(OR($N3="حاضر",$N3="دوام جزئي"),MAX(0,MOD($F3-$E3,1)*24-$I3),0)) | K3: =IF(OR($A3="",$E3=""),"",IF(AND(احتساب_التأخير="نعم",OR($N3="حاضر",$N3="دوام جزئي"),$E3>$G3+دقائق_السماح/1440),($E3-$G3-دقائق_السماح/1440)*24,0)) | L3: =IF(OR($A3="",$F3=""),"",IF(AND(OR($N3="حاضر",$N3="دوام جزئي"),$F3<$H3),($H3-$F3)*24,0)) | M3: =IF(OR($A3="",$F3=""),"",IF(AND(احتساب_العمل_الإضافي="نعم",OR($N3="حاضر",$N3="دوام جزئي"),$F3>$H3,($F3-$H3)*24*60>=حد_العمل_الإضافي_دقيقة),($F3-$H3)*24,0)) | Q3: =IF(AND(ISNUMBER($K3),$K3>0),SUMPRODUCT(ISNUMBER($K$3:$K$502)*($K$3:$K$502>0)*(ROW($K$3:$K$502)<=ROW())),"")
B4: =IFERROR(INDEX(الموظفون_الاسم,MATCH($A4,الموظفون_الرقم,0)),"") | D4: =IF($C4="","",IFERROR(INDEX(قائمة_أيام_الأسبوع,WEEKDAY($C4,1)),"")) | G4: =IF($A4="","",بداية_الدوام) | H4: =IF($A4="","",نهاية_الدوام) | I4: =IF($A4="","",مدة_الاستراحة/60) | J4: =IF(OR($A4="",$E4="",$F4=""),"",IF(OR($N4="حاضر",$N4="دوام جزئي"),MAX(0,MOD($F4-$E4,1)*24-$I4),0)) | K4: =IF(OR($A4="",$E4=""),"",IF(AND(احتساب_التأخير="نعم",OR($N4="حاضر",$N4="دوام جزئي"),$E4>$G4+دقائق_السماح/1440),($E4-$G4-دقائق_السماح/1440)*24,0)) | L4: =IF(OR($A4="",$F4=""),"",IF(AND(OR($N4="حاضر",$N4="دوام جزئي"),$F4<$H4),($H4-$F4)*24,0)) | M4: =IF(OR($A4="",$F4=""),"",IF(AND(احتساب_العمل_الإضافي="نعم",OR($N4="حاضر",$N4="دوام جزئي"),$F4>$H4,($F4-$H4)*24*60>=حد_العمل_الإضافي_دقيقة),($F4-$H4)*24,0)) | Q4: =IF(AND(ISNUMBER($K4),$K4>0),SUMPRODUCT(ISNUMBER($K$3:$K$502)*($K$3:$K$502>0)*(ROW($K$3:$K$502)<=ROW())),"")
B5: =IFERROR(INDEX(الموظفون_الاسم,MATCH($A5,الموظفون_الرقم,0)),"") | D5: =IF($C5="","",IFERROR(INDEX(قائمة_أيام_الأسبوع,WEEKDAY($C5,1)),"")) | G5: =IF($A5="","",بداية_الدوام) | H5: =IF($A5="","",نهاية_الدوام) | I5: =IF($A5="","",مدة_الاستراحة/60) | J5: =IF(OR($A5="",$E5="",$F5=""),"",IF(OR($N5="حاضر",$N5="دوام جزئي"),MAX(0,MOD($F5-$E5,1)*24-$I5),0)) | K5: =IF(OR($A5="",$E5=""),"",IF(AND(احتساب_التأخير="نعم",OR($N5="حاضر",$N5="دوام جزئي"),$E5>$G5+دقائق_السماح/1440),($E5-$G5-دقائق_السماح/1440)*24,0)) | L5: =IF(OR($A5="",$F5=""),"",IF(AND(OR($N5="حاضر",$N5="دوام جزئي"),$F5<$H5),($H5-$F5)*24,0)) | M5: =IF(OR($A5="",$F5=""),"",IF(AND(احتساب_العمل_الإضافي="نعم",OR($N5="حاضر",$N5="دوام جزئي"),$F5>$H5,($F5-$H5)*24*60>=حد_العمل_الإضافي_دقيقة),($F5-$H5)*24,0)) | Q5: =IF(AND(ISNUMBER($K5),$K5>0),SUMPRODUCT(ISNUMBER($K$3:$K$502)*($K$3:$K$502>0)*(ROW($K$3:$K$502)<=ROW())),"")
B6: =IFERROR(INDEX(الموظفون_الاسم,MATCH($A6,الموظفون_الرقم,0)),"") | D6: =IF($C6="","",IFERROR(INDEX(قائمة_أيام_الأسبوع,WEEKDAY($C6,1)),"")) | G6: =IF($A6="","",بداية_الدوام) | H6: =IF($A6="","",نهاية_الدوام) | I6: =IF($A6="","",مدة_الاستراحة/60) | J6: =IF(OR($A6="",$E6="",$F6=""),"",IF(OR($N6="حاضر",$N6="دوام جزئي"),MAX(0,MOD($F6-$E6,1)*24-$I6),0)) | K6: =IF(OR($A6="",$E6=""),"",IF(AND(احتساب_التأخير="نعم",OR($N6="حاضر",$N6="دوام جزئي"),$E6>$G6+دقائق_السماح/1440),($E6-$G6-دقائق_السماح/1440)*24,0)) | L6: =IF(OR($A6="",$F6=""),"",IF(AND(OR($N6="حاضر",$N6="دوام جزئي"),$F6<$H6),($H6-$F6)*24,0)) | M6: =IF(OR($A6="",$F6=""),"",IF(AND(احتساب_العمل_الإضافي="نعم",OR($N6="حاضر",$N6="دوام جزئي"),$F6>$H6,($F6-$H6)*24*60>=حد_العمل_الإضافي_دقيقة),($F6-$H6)*24,0)) | Q6: =IF(AND(ISNUMBER($K6),$K6>0),SUMPRODUCT(ISNUMBER($K$3:$K$502)*($K$3:$K$502>0)*(ROW($K$3:$K$502)<=ROW())),"")
B7: =IFERROR(INDEX(الموظفون_الاسم,MATCH($A7,الموظفون_الرقم,0)),"") | D7: =IF($C7="","",IFERROR(INDEX(قائمة_أيام_الأسبوع,WEEKDAY($C7,1)),"")) | G7: =IF($A7="","",بداية_الدوام) | H7: =IF($A7="","",نهاية_الدوام) | I7: =IF($A7="","",مدة_الاستراحة/60) | J7: =IF(OR($A7="",$E7="",$F7=""),"",IF(OR($N7="حاضر",$N7="دوام جزئي"),MAX(0,MOD($F7-$E7,1)*24-$I7),0)) | K7: =IF(OR($A7="",$E7=""),"",IF(AND(احتساب_التأخير="نعم",OR($N7="حاضر",$N7="دوام جزئي"),$E7>$G7+دقائق_السماح/1440),($E7-$G7-دقائق_السماح/1440)*24,0)) | L7: =IF(OR($A7="",$F7=""),"",IF(AND(OR($N7="حاضر",$N7="دوام جزئي"),$F7<$H7),($H7-$F7)*24,0)) | M7: =IF(OR($A7="",$F7=""),"",IF(AND(احتساب_العمل_الإضافي="نعم",OR($N7="حاضر",$N7="دوام جزئي"),$F7>$H7,($F7-$H7)*24*60>=حد_العمل_الإضافي_دقيقة),($F7-$H7)*24,0)) | Q7: =IF(AND(ISNUMBER($K7),$K7>0),SUMPRODUCT(ISNUMBER($K$3:$K$502)*($K$3:$K$502>0)*(ROW($K$3:$K$502)<=ROW())),"")
B8: =IFERROR(INDEX(الموظفون_الاسم,MATCH($A8,الموظفون_الرقم,0)),"") | D8: =IF($C8="","",IFERROR(INDEX(قائمة_أيام_الأسبوع,WEEKDAY($C8,1)),"")) | G8: =IF($A8="","",بداية_الدوام) | H8: =IF($A8="","",نهاية_الدوام) | I8: =IF($A8="","",مدة_الاستراحة/60) | J8: =IF(OR($A8="",$E8="",$F8=""),"",IF(OR($N8="حاضر",$N8="دوام جزئي"),MAX(0,MOD($F8-$E8,1)*24-$I8),0)) | K8: =IF(OR($A8="",$E8=""),"",IF(AND(احتساب_التأخير="نعم",OR($N8="حاضر",$N8="دوام جزئي"),$E8>$G8+دقائق_السماح/1440),($E8-$G8-دقائق_السماح/1440)*24,0)) | L8: =IF(OR($A8="",$F8=""),"",IF(AND(OR($N8="حاضر",$N8="دوام جزئي"),$F8<$H8),($H8-$F8)*24,0)) | M8: =IF(OR($A8="",$F8=""),"",IF(AND(احتساب_العمل_الإضافي="نعم",OR($N8="حاضر",$N8="دوام جزئي"),$F8>$H8,($F8-$H8)*24*60>=حد_العمل_الإضافي_دقيقة),($F8-$H8)*24,0)) | Q8: =IF(AND(ISNUMBER($K8),$K8>0),SUMPRODUCT(ISNUMBER($K$3:$K$502)*($K$3:$K$502>0)*(ROW($K$3:$K$502)<=ROW())),"")
B9: =IFERROR(INDEX(الموظفون_الاسم,MATCH($A9,الموظفون_الرقم,0)),"") | D9: =IF($C9="","",IFERROR(INDEX(قائمة_أيام_الأسبوع,WEEKDAY($C9,1)),"")) | G9: =IF($A9="","",بداية_الدوام) | H9: =IF($A9="","",نهاية_الدوام) | I9: =IF($A9="","",مدة_الاستراحة/60) | J9: =IF(OR($A9="",$E9="",$F9=""),"",IF(OR($N9="حاضر",$N9="دوام جزئي"),MAX(0,MOD($F9-$E9,1)*24-$I9),0)) | K9: =IF(OR($A9="",$E9=""),"",IF(AND(احتساب_التأخير="نعم",OR($N9="حاضر",$N9="دوام جزئي"),$E9>$G9+دقائق_السماح/1440),($E9-$G9-دقائق_السماح/1440)*24,0)) | L9: =IF(OR($A9="",$F9=""),"",IF(AND(OR($N9="حاضر",$N9="دوام جزئي"),$F9<$H9),($H9-$F9)*24,0)) | M9: =IF(OR($A9="",$F9=""),"",IF(AND(احتساب_العمل_الإضافي="نعم",OR($N9="حاضر",$N9="دوام جزئي"),$F9>$H9,($F9-$H9)*24*60>=حد_العمل_الإضافي_دقيقة),($F9-$H9)*24,0)) | Q9: =IF(AND(ISNUMBER($K9),$K9>0),SUMPRODUCT(ISNUMBER($K$3:$K$502)*($K$3:$K$502>0)*(ROW($K$3:$K$502)<=ROW())),"")
B10: =IFERROR(INDEX(الموظفون_الاسم,MATCH($A10,الموظفون_الرقم,0)),"") | D10: =IF($C10="","",IFERROR(INDEX(قائمة_أيام_الأسبوع,WEEKDAY($C10,1)),"")) | G10: =IF($A10="","",بداية_الدوام) | H10: =IF($A10="","",نهاية_الدوام) | I10: =IF($A10="","",مدة_الاستراحة/60) | J10: =IF(OR($A10="",$E10="",$F10=""),"",IF(OR($N10="حاضر",$N10="دوام جزئي"),MAX(0,MOD($F10-$E10,1)*24-$I10),0)) | K10: =IF(OR($A10="",$E10=""),"",IF(AND(احتساب_التأخير="نعم",OR($N10="حاضر",$N10="دوام جزئي"),$E10>$G10+دقائق_السماح/1440),($E10-$G10-دقائق_السماح/1440)*24,0)) | L10: =IF(OR($A10="",$F10=""),"",IF(AND(OR($N10="حاضر",$N10="دوام جزئي"),$F10<$H10),($H10-$F10)*24,0)) | M10: =IF(OR($A10="",$F10=""),"",IF(AND(احتساب_العمل_الإضافي="نعم",OR($N10="حاضر",$N10="دوام جزئي"),$F10>$H10,($F10-$H10)*24*60>=حد_العمل_الإضافي_دقيقة),($F10-$H10)*24,0)) | Q10: =IF(AND(ISNUMBER($K10),$K10>0),SUMPRODUCT(ISNUMBER($K$3:$K$502)*($K$3:$K$502>0)*(ROW($K$3:$K$502)<=ROW())),"")
B11: =IFERROR(INDEX(الموظفون_الاسم,MATCH($A11,الموظفون_الرقم,0)),"") | D11: =IF($C11="","",IFERROR(INDEX(قائمة_أيام_الأسبوع,WEEKDAY($C11,1)),"")) | G11: =IF($A11="","",بداية_الدوام) | H11: =IF($A11="","",نهاية_الدوام) | I11: =IF($A11="","",مدة_الاستراحة/60) | J11: =IF(OR($A11="",$E11="",$F11=""),"",IF(OR($N11="حاضر",$N11="دوام جزئي"),MAX(0,MOD($F11-$E11,1)*24-$I11),0)) | K11: =IF(OR($A11="",$E11=""),"",IF(AND(احتساب_التأخير="نعم",OR($N11="حاضر",$N11="دوام جزئي"),$E11>$G11+دقائق_السماح/1440),($E11-$G11-دقائق_السماح/1440)*24,0)) | L11: =IF(OR($A11="",$F11=""),"",IF(AND(OR($N11="حاضر",$N11="دوام جزئي"),$F11<$H11),($H11-$F11)*24,0)) | M11: =IF(OR($A11="",$F11=""),"",IF(AND(احتساب_العمل_الإضافي="نعم",OR($N11="حاضر",$N11="دوام جزئي"),$F11>$H11,($F11-$H11)*24*60>=حد_العمل_الإضافي_دقيقة),($F11-$H11)*24,0)) | Q11: =IF(AND(ISNUMBER($K11),$K11>0),SUMPRODUCT(ISNUMBER($K$3:$K$502)*($K$3:$K$502>0)*(ROW($K$3:$K$502)<=ROW())),"")
B12: =IFERROR(INDEX(الموظفون_الاسم,MATCH($A12,الموظفون_الرقم,0)),"") | D12: =IF($C12="","",IFERROR(INDEX(قائمة_أيام_الأسبوع,WEEKDAY($C12,1)),"")) | G12: =IF($A12="","",بداية_الدوام) | H12: =IF($A12="","",نهاية_الدوام) | I12: =IF($A12="","",مدة_الاستراحة/60) | J12: =IF(OR($A12="",$E12="",$F12=""),"",IF(OR($N12="حاضر",$N12="دوام جزئي"),MAX(0,MOD($F12-$E12,1)*24-$I12),0)) | K12: =IF(OR($A12="",$E12=""),"",IF(AND(احتساب_التأخير="نعم",OR($N12="حاضر",$N12="دوام جزئي"),$E12>$G12+دقائق_السماح/1440),($E12-$G12-دقائق_السماح/1440)*24,0)) | L12: =IF(OR($A12="",$F12=""),"",IF(AND(OR($N12="حاضر",$N12="دوام جزئي"),$F12<$H12),($H12-$F12)*24,0)) | M12: =IF(OR($A12="",$F12=""),"",IF(AND(احتساب_العمل_الإضافي="نعم",OR($N12="حاضر",$N12="دوام جزئي"),$F12>$H12,($F12-$H12)*24*60>=حد_العمل_الإضافي_دقيقة),($F12-$H12)*24,0)) | Q12: =IF(AND(ISNUMBER($K12),$K12>0),SUMPRODUCT(ISNUMBER($K$3:$K$502)*($K$3:$K$502>0)*(ROW($K$3:$K$502)<=ROW())),"")
B13: =IFERROR(INDEX(الموظفون_الاسم,MATCH($A13,الموظفون_الرقم,0)),"") | D13: =IF($C13="","",IFERROR(INDEX(قائمة_أيام_الأسبوع,WEEKDAY($C13,1)),"")) | G13: =IF($A13="","",بداية_الدوام) | H13: =IF($A13="","",نهاية_الدوام) | I13: =IF($A13="","",مدة_الاستراحة/60) | J13: =IF(OR($A13="",$E13="",$F13=""),"",IF(OR($N13="حاضر",$N13="دوام جزئي"),MAX(0,MOD($F13-$E13,1)*24-$I13),0)) | K13: =IF(OR($A13="",$E13=""),"",IF(AND(احتساب_التأخير="نعم",OR($N13="حاضر",$N13="دوام جزئي"),$E13>$G13+دقائق_السماح/1440),($E13-$G13-دقائق_السماح/1440)*24,0)) | L13: =IF(OR($A13="",$F13=""),"",IF(AND(OR($N13="حاضر",$N13="دوام جزئي"),$F13<$H13),($H13-$F13)*24,0)) | M13: =IF(OR($A13="",$F13=""),"",IF(AND(احتساب_العمل_الإضافي="نعم",OR($N13="حاضر",$N13="دوام جزئي"),$F13>$H13,($F13-$H13)*24*60>=حد_العمل_الإضافي_دقيقة),($F13-$H13)*24,0)) | Q13: =IF(AND(ISNUMBER($K13),$K13>0),SUMPRODUCT(ISNUMBER($K$3:$K$502)*($K$3:$K$502>0)*(ROW($K$3:$K$502)<=ROW())),"")
B14: =IFERROR(INDEX(الموظفون_الاسم,MATCH($A14,الموظفون_الرقم,0)),"") | D14: =IF($C14="","",IFERROR(INDEX(قائمة_أيام_الأسبوع,WEEKDAY($C14,1)),"")) | G14: =IF($A14="","",بداية_الدوام) | H14: =IF($A14="","",نهاية_الدوام) | I14: =IF($A14="","",مدة_الاستراحة/60) | J14: =IF(OR($A14="",$E14="",$F14=""),"",IF(OR($N14="حاضر",$N14="دوام جزئي"),MAX(0,MOD($F14-$E14,1)*24-$I14),0)) | K14: =IF(OR($A14="",$E14=""),"",IF(AND(احتساب_التأخير="نعم",OR($N14="حاضر",$N14="دوام جزئي"),$E14>$G14+دقائق_السماح/1440),($E14-$G14-دقائق_السماح/1440)*24,0)) | L14: =IF(OR($A14="",$F14=""),"",IF(AND(OR($N14="حاضر",$N14="دوام جزئي"),$F14<$H14),($H14-$F14)*24,0)) | M14: =IF(OR($A14="",$F14=""),"",IF(AND(احتساب_العمل_الإضافي="نعم",OR($N14="حاضر",$N14="دوام جزئي"),$F14>$H14,($F14-$H14)*24*60>=حد_العمل_الإضافي_دقيقة),($F14-$H14)*24,0)) | Q14: =IF(AND(ISNUMBER($K14),$K14>0),SUMPRODUCT(ISNUMBER($K$3:$K$502)*($K$3:$K$502>0)*(ROW($K$3:$K$502)<=ROW())),"")
... B502: =IFERROR(INDEX(الموظفون_الاسم,MATCH($A502,الموظفون_الرقم,0)),"") | D502: =IF($C502="","",IFERROR(INDEX(قائمة_أيام_الأسبوع,WEEKDAY($C502,1)),"")) | G502: =IF($A502="","",بداية_الدوام) | H502: =IF($A502="","",نهاية_الدوام) | I502: =IF($A502="","",مدة_الاستراحة/60) | J502: =IF(OR($A502="",$E502="",$F502=""),"",IF(OR($N502="حاضر",$N502="دوام جزئي"),MAX(0,MOD($F502-$E502,1)*24-$I502),0)) | K502: =IF(OR($A502="",$E502=""),"",IF(AND(احتساب_التأخير="نعم",OR($N502="حاضر",$N502="دوام جزئي"),$E502>$G502+دقائق_السماح/1440),($E502-$G502-دقائق_السماح/1440)*24,0)) | L502: =IF(OR($A502="",$F502=""),"",IF(AND(OR($N502="حاضر",$N502="دوام جزئي"),$F502<$H502),($H502-$F502)*24,0)) | M502: =IF(OR($A502="",$F502=""),"",IF(AND(احتساب_العمل_الإضافي="نعم",OR($N502="حاضر",$N502="دوام جزئي"),$F502>$H502,($F502-$H502)*24*60>=حد_العمل_الإضافي_دقيقة),($F502-$H502)*24,0)) | Q502: =IF(AND(ISNUMBER($K502),$K502>0),SUMPRODUCT(ISNUMBER($K$3:$K$502)*($K$3:$K$502>0)*(ROW($K$3:$K$502)<=ROW())),"")

Sheet الإجازات
A1: الإجازات — نموذج إدخال
A2: رقم الطلب | B2: الرقم الوظيفي | C2: اسم الموظف | D2: نوع الإجازة | E2: تاريخ تقديم الطلب | F2: تاريخ بداية الإجازة | G2: تاريخ نهاية الإجازة | H2: عدد الأيام | I2: الرصيد قبل الطلب | J2: الأيام المستخدمة | K2: الرصيد بعد الطلب | L2: حالة الطلب | M2: اسم المعتمد | N2: تاريخ الاعتماد | O2: الملاحظات
C3: =IFERROR(INDEX(الموظفون_الاسم,MATCH($B3,الموظفون_الرقم,0)),"") | H3: =IF(OR($F3="",$G3=""),"",MAX(0,$G3-$F3+1)) | I3: =IF($B3="","",IFERROR(INDEX(الموظفون_الافتتاحي,MATCH($B3,الموظفون_الرقم,0)),0)+IF($D3<>"سنوية",0,IFERROR(DATEDIF(بداية_احتساب_الرصيد,TODAY(),"M"),0)*معدل_الاستحقاق_الشهري)-SUMIFS($J$3:$J$502,$B$3:$B$502,$B3,$D$3:$D$502,"سنوية",$L$3:$L$502,"معتمد",$A$3:$A$502,"<"&$A3)) | J3: =IF($L3="معتمد",$H3,0) | K3: =IF($B3="","",$I3-$J3)
C4: =IFERROR(INDEX(الموظفون_الاسم,MATCH($B4,الموظفون_الرقم,0)),"") | H4: =IF(OR($F4="",$G4=""),"",MAX(0,$G4-$F4+1)) | I4: =IF($B4="","",IFERROR(INDEX(الموظفون_الافتتاحي,MATCH($B4,الموظفون_الرقم,0)),0)+IF($D4<>"سنوية",0,IFERROR(DATEDIF(بداية_احتساب_الرصيد,TODAY(),"M"),0)*معدل_الاستحقاق_الشهري)-SUMIFS($J$3:$J$502,$B$3:$B$502,$B4,$D$3:$D$502,"سنوية",$L$3:$L$502,"معتمد",$A$3:$A$502,"<"&$A4)) | J4: =IF($L4="معتمد",$H4,0) | K4: =IF($B4="","",$I4-$J4)
C5: =IFERROR(INDEX(الموظفون_الاسم,MATCH($B5,الموظفون_الرقم,0)),"") | H5: =IF(OR($F5="",$G5=""),"",MAX(0,$G5-$F5+1)) | I5: =IF($B5="","",IFERROR(INDEX(الموظفون_الافتتاحي,MATCH($B5,الموظفون_الرقم,0)),0)+IF($D5<>"سنوية",0,IFERROR(DATEDIF(بداية_احتساب_الرصيد,TODAY(),"M"),0)*معدل_الاستحقاق_الشهري)-SUMIFS($J$3:$J$502,$B$3:$B$502,$B5,$D$3:$D$502,"سنوية",$L$3:$L$502,"معتمد",$A$3:$A$502,"<"&$A5)) | J5: =IF($L5="معتمد",$H5,0) | K5: =IF($B5="","",$I5-$J5)
C6: =IFERROR(INDEX(الموظفون_الاسم,MATCH($B6,الموظفون_الرقم,0)),"") | H6: =IF(OR($F6="",$G6=""),"",MAX(0,$G6-$F6+1)) | I6: =IF($B6="","",IFERROR(INDEX(الموظفون_الافتتاحي,MATCH($B6,الموظفون_الرقم,0)),0)+IF($D6<>"سنوية",0,IFERROR(DATEDIF(بداية_احتساب_الرصيد,TODAY(),"M"),0)*معدل_الاستحقاق_الشهري)-SUMIFS($J$3:$J$502,$B$3:$B$502,$B6,$D$3:$D$502,"سنوية",$L$3:$L$502,"معتمد",$A$3:$A$502,"<"&$A6)) | J6: =IF($L6="معتمد",$H6,0) | K6: =IF($B6="","",$I6-$J6)
C7: =IFERROR(INDEX(الموظفون_الاسم,MATCH($B7,الموظفون_الرقم,0)),"") | H7: =IF(OR($F7="",$G7=""),"",MAX(0,$G7-$F7+1)) | I7: =IF($B7="","",IFERROR(INDEX(الموظفون_الافتتاحي,MATCH($B7,الموظفون_الرقم,0)),0)+IF($D7<>"سنوية",0,IFERROR(DATEDIF(بداية_احتساب_الرصيد,TODAY(),"M"),0)*معدل_الاستحقاق_الشهري)-SUMIFS($J$3:$J$502,$B$3:$B$502,$B7,$D$3:$D$502,"سنوية",$L$3:$L$502,"معتمد",$A$3:$A$502,"<"&$A7)) | J7: =IF($L7="معتمد",$H7,0) | K7: =IF($B7="","",$I7-$J7)
C8: =IFERROR(INDEX(الموظفون_الاسم,MATCH($B8,الموظفون_الرقم,0)),"") | H8: =IF(OR($F8="",$G8=""),"",MAX(0,$G8-$F8+1)) | I8: =IF($B8="","",IFERROR(INDEX(الموظفون_الافتتاحي,MATCH($B8,الموظفون_الرقم,0)),0)+IF($D8<>"سنوية",0,IFERROR(DATEDIF(بداية_احتساب_الرصيد,TODAY(),"M"),0)*معدل_الاستحقاق_الشهري)-SUMIFS($J$3:$J$502,$B$3:$B$502,$B8,$D$3:$D$502,"سنوية",$L$3:$L$502,"معتمد",$A$3:$A$502,"<"&$A8)) | J8: =IF($L8="معتمد",$H8,0) | K8: =IF($B8="","",$I8-$J8)
C9: =IFERROR(INDEX(الموظفون_الاسم,MATCH($B9,الموظفون_الرقم,0)),"") | H9: =IF(OR($F9="",$G9=""),"",MAX(0,$G9-$F9+1)) | I9: =IF($B9="","",IFERROR(INDEX(الموظفون_الافتتاحي,MATCH($B9,الموظفون_الرقم,0)),0)+IF($D9<>"سنوية",0,IFERROR(DATEDIF(بداية_احتساب_الرصيد,TODAY(),"M"),0)*معدل_الاستحقاق_الشهري)-SUMIFS($J$3:$J$502,$B$3:$B$502,$B9,$D$3:$D$502,"سنوية",$L$3:$L$502,"معتمد",$A$3:$A$502,"<"&$A9)) | J9: =IF($L9="معتمد",$H9,0) | K9: =IF($B9="","",$I9-$J9)
C10: =IFERROR(INDEX(الموظفون_الاسم,MATCH($B10,الموظفون_الرقم,0)),"") | H10: =IF(OR($F10="",$G10=""),"",MAX(0,$G10-$F10+1)) | I10: =IF($B10="","",IFERROR(INDEX(الموظفون_الافتتاحي,MATCH($B10,الموظفون_الرقم,0)),0)+IF($D10<>"سنوية",0,IFERROR(DATEDIF(بداية_احتساب_الرصيد,TODAY(),"M"),0)*معدل_الاستحقاق_الشهري)-SUMIFS($J$3:$J$502,$B$3:$B$502,$B10,$D$3:$D$502,"سنوية",$L$3:$L$502,"معتمد",$A$3:$A$502,"<"&$A10)) | J10: =IF($L10="معتمد",$H10,0) | K10: =IF($B10="","",$I10-$J10)
C11: =IFERROR(INDEX(الموظفون_الاسم,MATCH($B11,الموظفون_الرقم,0)),"") | H11: =IF(OR($F11="",$G11=""),"",MAX(0,$G11-$F11+1)) | I11: =IF($B11="","",IFERROR(INDEX(الموظفون_الافتتاحي,MATCH($B11,الموظفون_الرقم,0)),0)+IF($D11<>"سنوية",0,IFERROR(DATEDIF(بداية_احتساب_الرصيد,TODAY(),"M"),0)*معدل_الاستحقاق_الشهري)-SUMIFS($J$3:$J$502,$B$3:$B$502,$B11,$D$3:$D$502,"سنوية",$L$3:$L$502,"معتمد",$A$3:$A$502,"<"&$A11)) | J11: =IF($L11="معتمد",$H11,0) | K11: =IF($B11="","",$I11-$J11)
C12: =IFERROR(INDEX(الموظفون_الاسم,MATCH($B12,الموظفون_الرقم,0)),"") | H12: =IF(OR($F12="",$G12=""),"",MAX(0,$G12-$F12+1)) | I12: =IF($B12="","",IFERROR(INDEX(الموظفون_الافتتاحي,MATCH($B12,الموظفون_الرقم,0)),0)+IF($D12<>"سنوية",0,IFERROR(DATEDIF(بداية_احتساب_الرصيد,TODAY(),"M"),0)*معدل_الاستحقاق_الشهري)-SUMIFS($J$3:$J$502,$B$3:$B$502,$B12,$D$3:$D$502,"سنوية",$L$3:$L$502,"معتمد",$A$3:$A$502,"<"&$A12)) | J12: =IF($L12="معتمد",$H12,0) | K12: =IF($B12="","",$I12-$J12)
C13: =IFERROR(INDEX(الموظفون_الاسم,MATCH($B13,الموظفون_الرقم,0)),"") | H13: =IF(OR($F13="",$G13=""),"",MAX(0,$G13-$F13+1)) | I13: =IF($B13="","",IFERROR(INDEX(الموظفون_الافتتاحي,MATCH($B13,الموظفون_الرقم,0)),0)+IF($D13<>"سنوية",0,IFERROR(DATEDIF(بداية_احتساب_الرصيد,TODAY(),"M"),0)*معدل_الاستحقاق_الشهري)-SUMIFS($J$3:$J$502,$B$3:$B$502,$B13,$D$3:$D$502,"سنوية",$L$3:$L$502,"معتمد",$A$3:$A$502,"<"&$A13)) | J13: =IF($L13="معتمد",$H13,0) | K13: =IF($B13="","",$I13-$J13)
C14: =IFERROR(INDEX(الموظفون_الاسم,MATCH($B14,الموظفون_الرقم,0)),"") | H14: =IF(OR($F14="",$G14=""),"",MAX(0,$G14-$F14+1)) | I14: =IF($B14="","",IFERROR(INDEX(الموظفون_الافتتاحي,MATCH($B14,الموظفون_الرقم,0)),0)+IF($D14<>"سنوية",0,IFERROR(DATEDIF(بداية_احتساب_الرصيد,TODAY(),"M"),0)*معدل_الاستحقاق_الشهري)-SUMIFS($J$3:$J$502,$B$3:$B$502,$B14,$D$3:$D$502,"سنوية",$L$3:$L$502,"معتمد",$A$3:$A$502,"<"&$A14)) | J14: =IF($L14="معتمد",$H14,0) | K14: =IF($B14="","",$I14-$J14)
... C502: =IFERROR(INDEX(الموظفون_الاسم,MATCH($B502,الموظفون_الرقم,0)),"") | H502: =IF(OR($F502="",$G502=""),"",MAX(0,$G502-$F502+1)) | I502: =IF($B502="","",IFERROR(INDEX(الموظفون_الافتتاحي,MATCH($B502,الموظفون_الرقم,0)),0)+IF($D502<>"سنوية",0,IFERROR(DATEDIF(بداية_احتساب_الرصيد,TODAY(),"M"),0)*معدل_الاستحقاق_الشهري)-SUMIFS($J$3:$J$502,$B$3:$B$502,$B502,$D$3:$D$502,"سنوية",$L$3:$L$502,"معتمد",$A$3:$A$502,"<"&$A502)) | J502: =IF($L502="معتمد",$H502,0) | K502: =IF($B502="","",$I502-$J502)

Sheet الرواتب
A1: الرواتب — نموذج إدخال
A2: الشهر | B2: السنة | C2: الرقم الوظيفي | D2: اسم الموظف | E2: الإدارة | F2: القسم | G2: الراتب الأساسي | H2: بدل النقل | I2: بدل السكن | J2: بدلات أخرى | K2: المكافآت | L2: قيمة العمل الإضافي | M2: رقم السلفة | N2: خصم تأخير | O2: خصم غياب | P2: خصم جزاء | Q2: قسط سلفة | R2: استقطاعات أخرى | S2: إجمالي الاستحقاقات | T2: إجمالي الخصومات | U2: صافي الراتب | V2: حالة الصرف | W2: تاريخ الصرف | X2: ملاحظات | Y2: تحقق (تكرار الشهر)
D3: =IFERROR(INDEX(الموظفون_الاسم,MATCH($C3,الموظفون_الرقم,0)),"") | E3: =IFERROR(INDEX(الموظفون_الإدارة,MATCH($C3,الموظفون_الرقم,0)),"") | F3: =IFERROR(INDEX(الموظفون_القسم,MATCH($C3,الموظفون_الرقم,0)),"") | G3: =IF($C3="","",IFERROR(INDEX(الموظفون_الاساسي,MATCH($C3,الموظفون_الرقم,0)),0)) | S3: =IF($C3="","",SUM($G3:$L3)) | T3: =IF($C3="","",SUM($N3:$R3)) | U3: =IF($C3="","",$S3-$T3) | Y3: =IF($C3="","",IF(SUMPRODUCT(($C$3:$C$502=$C3)*($A$3:$A$502=$A3)*($B$3:$B$502=$B3))>1,"⚠ مكرر","سليم")) | Z3: =IF(AND($C3<>"",$A3=تقرير_الشهر,$B3=تقرير_السنة),SUMPRODUCT(($C$3:$C$502<>"")*($A$3:$A$502=تقرير_الشهر)*($B$3:$B$502=تقرير_السنة)*(ROW($C$3:$C$502)<=ROW())),"")
D4: =IFERROR(INDEX(الموظفون_الاسم,MATCH($C4,الموظفون_الرقم,0)),"") | E4: =IFERROR(INDEX(الموظفون_الإدارة,MATCH($C4,الموظفون_الرقم,0)),"") | F4: =IFERROR(INDEX(الموظفون_القسم,MATCH($C4,الموظفون_الرقم,0)),"") | G4: =IF($C4="","",IFERROR(INDEX(الموظفون_الاساسي,MATCH($C4,الموظفون_الرقم,0)),0)) | S4: =IF($C4="","",SUM($G4:$L4)) | T4: =IF($C4="","",SUM($N4:$R4)) | U4: =IF($C4="","",$S4-$T4) | Y4: =IF($C4="","",IF(SUMPRODUCT(($C$3:$C$502=$C4)*($A$3:$A$502=$A4)*($B$3:$B$502=$B4))>1,"⚠ مكرر","سليم")) | Z4: =IF(AND($C4<>"",$A4=تقرير_الشهر,$B4=تقرير_السنة),SUMPRODUCT(($C$3:$C$502<>"")*($A$3:$A$502=تقرير_الشهر)*($B$3:$B$502=تقرير_السنة)*(ROW($C$3:$C$502)<=ROW())),"")
D5: =IFERROR(INDEX(الموظفون_الاسم,MATCH($C5,الموظفون_الرقم,0)),"") | E5: =IFERROR(INDEX(الموظفون_الإدارة,MATCH($C5,الموظفون_الرقم,0)),"") | F5: =IFERROR(INDEX(الموظفون_القسم,MATCH($C5,الموظفون_الرقم,0)),"") | G5: =IF($C5="","",IFERROR(INDEX(الموظفون_الاساسي,MATCH($C5,الموظفون_الرقم,0)),0)) | S5: =IF($C5="","",SUM($G5:$L5)) | T5: =IF($C5="","",SUM($N5:$R5)) | U5: =IF($C5="","",$S5-$T5) | Y5: =IF($C5="","",IF(SUMPRODUCT(($C$3:$C$502=$C5)*($A$3:$A$502=$A5)*($B$3:$B$502=$B5))>1,"⚠ مكرر","سليم")) | Z5: =IF(AND($C5<>"",$A5=تقرير_الشهر,$B5=تقرير_السنة),SUMPRODUCT(($C$3:$C$502<>"")*($A$3:$A$502=تقرير_الشهر)*($B$3:$B$502=تقرير_السنة)*(ROW($C$3:$C$502)<=ROW())),"")
D6: =IFERROR(INDEX(الموظفون_الاسم,MATCH($C6,الموظفون_الرقم,0)),"") | E6: =IFERROR(INDEX(الموظفون_الإدارة,MATCH($C6,الموظفون_الرقم,0)),"") | F6: =IFERROR(INDEX(الموظفون_القسم,MATCH($C6,الموظفون_الرقم,0)),"") | G6: =IF($C6="","",IFERROR(INDEX(الموظفون_الاساسي,MATCH($C6,الموظفون_الرقم,0)),0)) | S6: =IF($C6="","",SUM($G6:$L6)) | T6: =IF($C6="","",SUM($N6:$R6)) | U6: =IF($C6="","",$S6-$T6) | Y6: =IF($C6="","",IF(SUMPRODUCT(($C$3:$C$502=$C6)*($A$3:$A$502=$A6)*($B$3:$B$502=$B6))>1,"⚠ مكرر","سليم")) | Z6: =IF(AND($C6<>"",$A6=تقرير_الشهر,$B6=تقرير_السنة),SUMPRODUCT(($C$3:$C$502<>"")*($A$3:$A$502=تقرير_الشهر)*($B$3:$B$502=تقرير_السنة)*(ROW($C$3:$C$502)<=ROW())),"")
D7: =IFERROR(INDEX(الموظفون_الاسم,MATCH($C7,الموظفون_الرقم,0)),"") | E7: =IFERROR(INDEX(الموظفون_الإدارة,MATCH($C7,الموظفون_الرقم,0)),"") | F7: =IFERROR(INDEX(الموظفون_القسم,MATCH($C7,الموظفون_الرقم,0)),"") | G7: =IF($C7="","",IFERROR(INDEX(الموظفون_الاساسي,MATCH($C7,الموظفون_الرقم,0)),0)) | S7: =IF($C7="","",SUM($G7:$L7)) | T7: =IF($C7="","",SUM($N7:$R7)) | U7: =IF($C7="","",$S7-$T7) | Y7: =IF($C7="","",IF(SUMPRODUCT(($C$3:$C$502=$C7)*($A$3:$A$502=$A7)*($B$3:$B$502=$B7))>1,"⚠ مكرر","سليم")) | Z7: =IF(AND($C7<>"",$A7=تقرير_الشهر,$B7=تقرير_السنة),SUMPRODUCT(($C$3:$C$502<>"")*($A$3:$A$502=تقرير_الشهر)*($B$3:$B$502=تقرير_السنة)*(ROW($C$3:$C$502)<=ROW())),"")
D8: =IFERROR(INDEX(الموظفون_الاسم,MATCH($C8,الموظفون_الرقم,0)),"") | E8: =IFERROR(INDEX(الموظفون_الإدارة,MATCH($C8,الموظفون_الرقم,0)),"") | F8: =IFERROR(INDEX(الموظفون_القسم,MATCH($C8,الموظفون_الرقم,0)),"") | G8: =IF($C8="","",IFERROR(INDEX(الموظفون_الاساسي,MATCH($C8,الموظفون_الرقم,0)),0)) | S8: =IF($C8="","",SUM($G8:$L8)) | T8: =IF($C8="","",SUM($N8:$R8)) | U8: =IF($C8="","",$S8-$T8) | Y8: =IF($C8="","",IF(SUMPRODUCT(($C$3:$C$502=$C8)*($A$3:$A$502=$A8)*($B$3:$B$502=$B8))>1,"⚠ مكرر","سليم")) | Z8: =IF(AND($C8<>"",$A8=تقرير_الشهر,$B8=تقرير_السنة),SUMPRODUCT(($C$3:$C$502<>"")*($A$3:$A$502=تقرير_الشهر)*($B$3:$B$502=تقرير_السنة)*(ROW($C$3:$C$502)<=ROW())),"")
D9: =IFERROR(INDEX(الموظفون_الاسم,MATCH($C9,الموظفون_الرقم,0)),"") | E9: =IFERROR(INDEX(الموظفون_الإدارة,MATCH($C9,الموظفون_الرقم,0)),"") | F9: =IFERROR(INDEX(الموظفون_القسم,MATCH($C9,الموظفون_الرقم,0)),"") | G9: =IF($C9="","",IFERROR(INDEX(الموظفون_الاساسي,MATCH($C9,الموظفون_الرقم,0)),0)) | S9: =IF($C9="","",SUM($G9:$L9)) | T9: =IF($C9="","",SUM($N9:$R9)) | U9: =IF($C9="","",$S9-$T9) | Y9: =IF($C9="","",IF(SUMPRODUCT(($C$3:$C$502=$C9)*($A$3:$A$502=$A9)*($B$3:$B$502=$B9))>1,"⚠ مكرر","سليم")) | Z9: =IF(AND($C9<>"",$A9=تقرير_الشهر,$B9=تقرير_السنة),SUMPRODUCT(($C$3:$C$502<>"")*($A$3:$A$502=تقرير_الشهر)*($B$3:$B$502=تقرير_السنة)*(ROW($C$3:$C$502)<=ROW())),"")
D10: =IFERROR(INDEX(الموظفون_الاسم,MATCH($C10,الموظفون_الرقم,0)),"") | E10: =IFERROR(INDEX(الموظفون_الإدارة,MATCH($C10,الموظفون_الرقم,0)),"") | F10: =IFERROR(INDEX(الموظفون_القسم,MATCH($C10,الموظفون_الرقم,0)),"") | G10: =IF($C10="","",IFERROR(INDEX(الموظفون_الاساسي,MATCH($C10,الموظفون_الرقم,0)),0)) | S10: =IF($C10="","",SUM($G10:$L10)) | T10: =IF($C10="","",SUM($N10:$R10)) | U10: =IF($C10="","",$S10-$T10) | Y10: =IF($C10="","",IF(SUMPRODUCT(($C$3:$C$502=$C10)*($A$3:$A$502=$A10)*($B$3:$B$502=$B10))>1,"⚠ مكرر","سليم")) | Z10: =IF(AND($C10<>"",$A10=تقرير_الشهر,$B10=تقرير_السنة),SUMPRODUCT(($C$3:$C$502<>"")*($A$3:$A$502=تقرير_الشهر)*($B$3:$B$502=تقرير_السنة)*(ROW($C$3:$C$502)<=ROW())),"")
D11: =IFERROR(INDEX(الموظفون_الاسم,MATCH($C11,الموظفون_الرقم,0)),"") | E11: =IFERROR(INDEX(الموظفون_الإدارة,MATCH($C11,الموظفون_الرقم,0)),"") | F11: =IFERROR(INDEX(الموظفون_القسم,MATCH($C11,الموظفون_الرقم,0)),"") | G11: =IF($C11="","",IFERROR(INDEX(الموظفون_الاساسي,MATCH($C11,الموظفون_الرقم,0)),0)) | S11: =IF($C11="","",SUM($G11:$L11)) | T11: =IF($C11="","",SUM($N11:$R11)) | U11: =IF($C11="","",$S11-$T11) | Y11: =IF($C11="","",IF(SUMPRODUCT(($C$3:$C$502=$C11)*($A$3:$A$502=$A11)*($B$3:$B$502=$B11))>1,"⚠ مكرر","سليم")) | Z11: =IF(AND($C11<>"",$A11=تقرير_الشهر,$B11=تقرير_السنة),SUMPRODUCT(($C$3:$C$502<>"")*($A$3:$A$502=تقرير_الشهر)*($B$3:$B$502=تقرير_السنة)*(ROW($C$3:$C$502)<=ROW())),"")
D12: =IFERROR(INDEX(الموظفون_الاسم,MATCH($C12,الموظفون_الرقم,0)),"") | E12: =IFERROR(INDEX(الموظفون_الإدارة,MATCH($C12,الموظفون_الرقم,0)),"") | F12: =IFERROR(INDEX(الموظفون_القسم,MATCH($C12,الموظفون_الرقم,0)),"") | G12: =IF($C12="","",IFERROR(INDEX(الموظفون_الاساسي,MATCH($C12,الموظفون_الرقم,0)),0)) | S12: =IF($C12="","",SUM($G12:$L12)) | T12: =IF($C12="","",SUM($N12:$R12)) | U12: =IF($C12="","",$S12-$T12) | Y12: =IF($C12="","",IF(SUMPRODUCT(($C$3:$C$502=$C12)*($A$3:$A$502=$A12)*($B$3:$B$502=$B12))>1,"⚠ مكرر","سليم")) | Z12: =IF(AND($C12<>"",$A12=تقرير_الشهر,$B12=تقرير_السنة),SUMPRODUCT(($C$3:$C$502<>"")*($A$3:$A$502=تقرير_الشهر)*($B$3:$B$502=تقرير_السنة)*(ROW($C$3:$C$502)<=ROW())),"")
D13: =IFERROR(INDEX(الموظفون_الاسم,MATCH($C13,الموظفون_الرقم,0)),"") | E13: =IFERROR(INDEX(الموظفون_الإدارة,MATCH($C13,الموظفون_الرقم,0)),"") | F13: =IFERROR(INDEX(الموظفون_القسم,MATCH($C13,الموظفون_الرقم,0)),"") | G13: =IF($C13="","",IFERROR(INDEX(الموظفون_الاساسي,MATCH($C13,الموظفون_الرقم,0)),0)) | S13: =IF($C13="","",SUM($G13:$L13)) | T13: =IF($C13="","",SUM($N13:$R13)) | U13: =IF($C13="","",$S13-$T13) | Y13: =IF($C13="","",IF(SUMPRODUCT(($C$3:$C$502=$C13)*($A$3:$A$502=$A13)*($B$3:$B$502=$B13))>1,"⚠ مكرر","سليم")) | Z13: =IF(AND($C13<>"",$A13=تقرير_الشهر,$B13=تقرير_السنة),SUMPRODUCT(($C$3:$C$502<>"")*($A$3:$A$502=تقرير_الشهر)*($B$3:$B$502=تقرير_السنة)*(ROW($C$3:$C$502)<=ROW())),"")
D14: =IFERROR(INDEX(الموظفون_الاسم,MATCH($C14,الموظفون_الرقم,0)),"") | E14: =IFERROR(INDEX(الموظفون_الإدارة,MATCH($C14,الموظفون_الرقم,0)),"") | F14: =IFERROR(INDEX(الموظفون_القسم,MATCH($C14,الموظفون_الرقم,0)),"") | G14: =IF($C14="","",IFERROR(INDEX(الموظفون_الاساسي,MATCH($C14,الموظفون_الرقم,0)),0)) | S14: =IF($C14="","",SUM($G14:$L14)) | T14: =IF($C14="","",SUM($N14:$R14)) | U14: =IF($C14="","",$S14-$T14) | Y14: =IF($C14="","",IF(SUMPRODUCT(($C$3:$C$502=$C14)*($A$3:$A$502=$A14)*($B$3:$B$502=$B14))>1,"⚠ مكرر","سليم")) | Z14: =IF(AND($C14<>"",$A14=تقرير_الشهر,$B14=تقرير_السنة),SUMPRODUCT(($C$3:$C$502<>"")*($A$3:$A$502=تقرير_الشهر)*($B$3:$B$502=تقرير_السنة)*(ROW($C$3:$C$502)<=ROW())),"")
... D502: =IFERROR(INDEX(الموظفون_الاسم,MATCH($C502,الموظفون_الرقم,0)),"") | E502: =IFERROR(INDEX(الموظفون_الإدارة,MATCH($C502,الموظفون_الرقم,0)),"") | F502: =IFERROR(INDEX(الموظفون_القسم,MATCH($C502,الموظفون_الرقم,0)),"") | G502: =IF($C502="","",IFERROR(INDEX(الموظفون_الاساسي,MATCH($C502,الموظفون_الرقم,0)),0)) | S502: =IF($C502="","",SUM($G502:$L502)) | T502: =IF($C502="","",SUM($N502:$R502)) | U502: =IF($C502="","",$S502-$T502) | Y502: =IF($C502="","",IF(SUMPRODUCT(($C$3:$C$502=$C502)*($A$3:$A$502=$A502)*($B$3:$B$502=$B502))>1,"⚠ مكرر","سليم")) | Z502: =IF(AND($C502<>"",$A502=تقرير_الشهر,$B502=تقرير_السنة),SUMPRODUCT(($C$3:$C$502<>"")*($A$3:$A$502=تقرير_الشهر)*($B$3:$B$502=تقرير_السنة)*(ROW($C$3:$C$502)<=ROW())),"")

Sheet السلف
A1: السلف — نموذج إدخال
A2: رقم السلفة | B2: الرقم الوظيفي | C2: اسم الموظف | D2: تاريخ السلفة | E2: مبلغ السلفة | F2: عدد الأقساط | G2: قيمة القسط | H2: إجمالي المسدد | I2: المبلغ المتبقي | J2: تاريخ بداية السداد | K2: حالة السلفة | L2: الملاحظات
C3: =IFERROR(INDEX(الموظفون_الاسم,MATCH($B3,الموظفون_الرقم,0)),"") | G3: =IF(OR($E3="",$F3="",$F3=0),"",$E3/$F3) | H3: =IF($A3="","",SUMIFS(الرواتب_قسط_السلفة,الرواتب_السلفة,$A3,الرواتب_حالة_الصرف,"مصروف")) | I3: =IF($A3="","",MAX(0,$E3-$H3))
C4: =IFERROR(INDEX(الموظفون_الاسم,MATCH($B4,الموظفون_الرقم,0)),"") | G4: =IF(OR($E4="",$F4="",$F4=0),"",$E4/$F4) | H4: =IF($A4="","",SUMIFS(الرواتب_قسط_السلفة,الرواتب_السلفة,$A4,الرواتب_حالة_الصرف,"مصروف")) | I4: =IF($A4="","",MAX(0,$E4-$H4))
C5: =IFERROR(INDEX(الموظفون_الاسم,MATCH($B5,الموظفون_الرقم,0)),"") | G5: =IF(OR($E5="",$F5="",$F5=0),"",$E5/$F5) | H5: =IF($A5="","",SUMIFS(الرواتب_قسط_السلفة,الرواتب_السلفة,$A5,الرواتب_حالة_الصرف,"مصروف")) | I5: =IF($A5="","",MAX(0,$E5-$H5))
C6: =IFERROR(INDEX(الموظفون_الاسم,MATCH($B6,الموظفون_الرقم,0)),"") | G6: =IF(OR($E6="",$F6="",$F6=0),"",$E6/$F6) | H6: =IF($A6="","",SUMIFS(الرواتب_قسط_السلفة,الرواتب_السلفة,$A6,الرواتب_حالة_الصرف,"مصروف")) | I6: =IF($A6="","",MAX(0,$E6-$H6))
C7: =IFERROR(INDEX(الموظفون_الاسم,MATCH($B7,الموظفون_الرقم,0)),"") | G7: =IF(OR($E7="",$F7="",$F7=0),"",$E7/$F7) | H7: =IF($A7="","",SUMIFS(الرواتب_قسط_السلفة,الرواتب_السلفة,$A7,الرواتب_حالة_الصرف,"مصروف")) | I7: =IF($A7="","",MAX(0,$E7-$H7))
C8: =IFERROR(INDEX(الموظفون_الاسم,MATCH($B8,الموظفون_الرقم,0)),"") | G8: =IF(OR($E8="",$F8="",$F8=0),"",$E8/$F8) | H8: =IF($A8="","",SUMIFS(الرواتب_قسط_السلفة,الرواتب_السلفة,$A8,الرواتب_حالة_الصرف,"مصروف")) | I8: =IF($A8="","",MAX(0,$E8-$H8))
C9: =IFERROR(INDEX(الموظفون_الاسم,MATCH($B9,الموظفون_الرقم,0)),"") | G9: =IF(OR($E9="",$F9="",$F9=0),"",$E9/$F9) | H9: =IF($A9="","",SUMIFS(الرواتب_قسط_السلفة,الرواتب_السلفة,$A9,الرواتب_حالة_الصرف,"مصروف")) | I9: =IF($A9="","",MAX(0,$E9-$H9))
C10: =IFERROR(INDEX(الموظفون_الاسم,MATCH($B10,الموظفون_الرقم,0)),"") | G10: =IF(OR($E10="",$F10="",$F10=0),"",$E10/$F10) | H10: =IF($A10="","",SUMIFS(الرواتب_قسط_السلفة,الرواتب_السلفة,$A10,الرواتب_حالة_الصرف,"مصروف")) | I10: =IF($A10="","",MAX(0,$E10-$H10))
C11: =IFERROR(INDEX(الموظفون_الاسم,MATCH($B11,الموظفون_الرقم,0)),"") | G11: =IF(OR($E11="",$F11="",$F11=0),"",$E11/$F11) | H11: =IF($A11="","",SUMIFS(الرواتب_قسط_السلفة,الرواتب_السلفة,$A11,الرواتب_حالة_الصرف,"مصروف")) | I11: =IF($A11="","",MAX(0,$E11-$H11))
C12: =IFERROR(INDEX(الموظفون_الاسم,MATCH($B12,الموظفون_الرقم,0)),"") | G12: =IF(OR($E12="",$F12="",$F12=0),"",$E12/$F12) | H12: =IF($A12="","",SUMIFS(الرواتب_قسط_السلفة,الرواتب_السلفة,$A12,الرواتب_حالة_الصرف,"مصروف")) | I12: =IF($A12="","",MAX(0,$E12-$H12))
C13: =IFERROR(INDEX(الموظفون_الاسم,MATCH($B13,الموظفون_الرقم,0)),"") | G13: =IF(OR($E13="",$F13="",$F13=0),"",$E13/$F13) | H13: =IF($A13="","",SUMIFS(الرواتب_قسط_السلفة,الرواتب_السلفة,$A13,الرواتب_حالة_الصرف,"مصروف")) | I13: =IF($A13="","",MAX(0,$E13-$H13))
C14: =IFERROR(INDEX(الموظفون_الاسم,MATCH($B14,الموظفون_الرقم,0)),"") | G14: =IF(OR($E14="",$F14="",$F14=0),"",$E14/$F14) | H14: =IF($A14="","",SUMIFS(الرواتب_قسط_السلفة,الرواتب_السلفة,$A14,الرواتب_حالة_الصرف,"مصروف")) | I14: =IF($A14="","",MAX(0,$E14-$H14))
... C502: =IFERROR(INDEX(الموظفون_الاسم,MATCH($B502,الموظفون_الرقم,0)),"") | G502: =IF(OR($E502="",$F502="",$F502=0),"",$E502/$F502) | H502: =IF($A502="","",SUMIFS(الرواتب_قسط_السلفة,الرواتب_السلفة,$A502,الرواتب_حالة_الصرف,"مصروف")) | I502: =IF($A502="","",MAX(0,$E502-$H502))

Sheet الوثائق
A1: الوثائق — نموذج إدخال
A2: الرقم الوظيفي | B2: اسم الموظف | C2: نوع الوثيقة | D2: رقم الوثيقة | E2: تاريخ الإصدار | F2: تاريخ الانتهاء | G2: الجهة المصدرة | H2: حالة الوثيقة | I2: أيام للانتهاء | J2: الملاحظات
B3: =IFERROR(INDEX(الموظفون_الاسم,MATCH($A3,الموظفون_الرقم,0)),"") | I3: =IF(OR($A3="",$F3=""),"",$F3-TODAY()) | K3: =IF(AND(ISNUMBER($I3),$I3<=تنبيه_وثيقة_90),SUMPRODUCT(ISNUMBER($I$3:$I$502)*($I$3:$I$502<=تنبيه_وثيقة_90)*(ROW($I$3:$I$502)<=ROW())),"")
B4: =IFERROR(INDEX(الموظفون_الاسم,MATCH($A4,الموظفون_الرقم,0)),"") | I4: =IF(OR($A4="",$F4=""),"",$F4-TODAY()) | K4: =IF(AND(ISNUMBER($I4),$I4<=تنبيه_وثيقة_90),SUMPRODUCT(ISNUMBER($I$3:$I$502)*($I$3:$I$502<=تنبيه_وثيقة_90)*(ROW($I$3:$I$502)<=ROW())),"")
B5: =IFERROR(INDEX(الموظفون_الاسم,MATCH($A5,الموظفون_الرقم,0)),"") | I5: =IF(OR($A5="",$F5=""),"",$F5-TODAY()) | K5: =IF(AND(ISNUMBER($I5),$I5<=تنبيه_وثيقة_90),SUMPRODUCT(ISNUMBER($I$3:$I$502)*($I$3:$I$502<=تنبيه_وثيقة_90)*(ROW($I$3:$I$502)<=ROW())),"")
B6: =IFERROR(INDEX(الموظفون_الاسم,MATCH($A6,الموظفون_الرقم,0)),"") | I6: =IF(OR($A6="",$F6=""),"",$F6-TODAY()) | K6: =IF(AND(ISNUMBER($I6),$I6<=تنبيه_وثيقة_90),SUMPRODUCT(ISNUMBER($I$3:$I$502)*($I$3:$I$502<=تنبيه_وثيقة_90)*(ROW($I$3:$I$502)<=ROW())),"")
B7: =IFERROR(INDEX(الموظفون_الاسم,MATCH($A7,الموظفون_الرقم,0)),"") | I7: =IF(OR($A7="",$F7=""),"",$F7-TODAY()) | K7: =IF(AND(ISNUMBER($I7),$I7<=تنبيه_وثيقة_90),SUMPRODUCT(ISNUMBER($I$3:$I$502)*($I$3:$I$502<=تنبيه_وثيقة_90)*(ROW($I$3:$I$502)<=ROW())),"")
B8: =IFERROR(INDEX(الموظفون_الاسم,MATCH($A8,الموظفون_الرقم,0)),"") | I8: =IF(OR($A8="",$F8=""),"",$F8-TODAY()) | K8: =IF(AND(ISNUMBER($I8),$I8<=تنبيه_وثيقة_90),SUMPRODUCT(ISNUMBER($I$3:$I$502)*($I$3:$I$502<=تنبيه_وثيقة_90)*(ROW($I$3:$I$502)<=ROW())),"")
B9: =IFERROR(INDEX(الموظفون_الاسم,MATCH($A9,الموظفون_الرقم,0)),"") | I9: =IF(OR($A9="",$F9=""),"",$F9-TODAY()) | K9: =IF(AND(ISNUMBER($I9),$I9<=تنبيه_وثيقة_90),SUMPRODUCT(ISNUMBER($I$3:$I$502)*($I$3:$I$502<=تنبيه_وثيقة_90)*(ROW($I$3:$I$502)<=ROW())),"")
B10: =IFERROR(INDEX(الموظفون_الاسم,MATCH($A10,الموظفون_الرقم,0)),"") | I10: =IF(OR($A10="",$F10=""),"",$F10-TODAY()) | K10: =IF(AND(ISNUMBER($I10),$I10<=تنبيه_وثيقة_90),SUMPRODUCT(ISNUMBER($I$3:$I$502)*($I$3:$I$502<=تنبيه_وثيقة_90)*(ROW($I$3:$I$502)<=ROW())),"")
B11: =IFERROR(INDEX(الموظفون_الاسم,MATCH($A11,الموظفون_الرقم,0)),"") | I11: =IF(OR($A11="",$F11=""),"",$F11-TODAY()) | K11: =IF(AND(ISNUMBER($I11),$I11<=تنبيه_وثيقة_90),SUMPRODUCT(ISNUMBER($I$3:$I$502)*($I$3:$I$502<=تنبيه_وثيقة_90)*(ROW($I$3:$I$502)<=ROW())),"")
B12: =IFERROR(INDEX(الموظفون_الاسم,MATCH($A12,الموظفون_الرقم,0)),"") | I12: =IF(OR($A12="",$F12=""),"",$F12-TODAY()) | K12: =IF(AND(ISNUMBER($I12),$I12<=تنبيه_وثيقة_90),SUMPRODUCT(ISNUMBER($I$3:$I$502)*($I$3:$I$502<=تنبيه_وثيقة_90)*(ROW($I$3:$I$502)<=ROW())),"")
B13: =IFERROR(INDEX(الموظفون_الاسم,MATCH($A13,الموظفون_الرقم,0)),"") | I13: =IF(OR($A13="",$F13=""),"",$F13-TODAY()) | K13: =IF(AND(ISNUMBER($I13),$I13<=تنبيه_وثيقة_90),SUMPRODUCT(ISNUMBER($I$3:$I$502)*($I$3:$I$502<=تنبيه_وثيقة_90)*(ROW($I$3:$I$502)<=ROW())),"")
B14: =IFERROR(INDEX(الموظفون_الاسم,MATCH($A14,الموظفون_الرقم,0)),"") | I14: =IF(OR($A14="",$F14=""),"",$F14-TODAY()) | K14: =IF(AND(ISNUMBER($I14),$I14<=تنبيه_وثيقة_90),SUMPRODUCT(ISNUMBER($I$3:$I$502)*($I$3:$I$502<=تنبيه_وثيقة_90)*(ROW($I$3:$I$502)<=ROW())),"")
... B502: =IFERROR(INDEX(الموظفون_الاسم,MATCH($A502,الموظفون_الرقم,0)),"") | I502: =IF(OR($A502="",$F502=""),"",$F502-TODAY()) | K502: =IF(AND(ISNUMBER($I502),$I502<=تنبيه_وثيقة_90),SUMPRODUCT(ISNUMBER($I$3:$I$502)*($I$3:$I$502<=تنبيه_وثيقة_90)*(ROW($I$3:$I$502)<=ROW())),"")

Sheet التوظيف
A1: التوظيف — نموذج إدخال
A2: رقم الطلب | B2: اسم المتقدم | C2: الوظيفة المطلوبة | D2: الإدارة المطلوبة | E2: المؤهل | F2: سنوات الخبرة | G2: تاريخ التقديم | H2: حالة الطلب | I2: موعد المقابلة | J2: نتيجة المقابلة | K2: القرار النهائي | L2: تاريخ المباشرة المتوقع | M2: الملاحظات

Sheet التدريب
A1: التدريب — نموذج إدخال
A2: الرقم الوظيفي | B2: اسم الموظف | C2: اسم الدورة | D2: الجهة التدريبية | E2: تاريخ البداية | F2: تاريخ النهاية | G2: التكلفة | H2: حالة الحضور | I2: نتيجة التدريب | J2: الملاحظات
B3: =IFERROR(INDEX(الموظفون_الاسم,MATCH($A3,الموظفون_الرقم,0)),"")
B4: =IFERROR(INDEX(الموظفون_الاسم,MATCH($A4,الموظفون_الرقم,0)),"")
B5: =IFERROR(INDEX(الموظفون_الاسم,MATCH($A5,الموظفون_الرقم,0)),"")
B6: =IFERROR(INDEX(الموظفون_الاسم,MATCH($A6,الموظفون_الرقم,0)),"")
B7: =IFERROR(INDEX(الموظفون_الاسم,MATCH($A7,الموظفون_الرقم,0)),"")
B8: =IFERROR(INDEX(الموظفون_الاسم,MATCH($A8,الموظفون_الرقم,0)),"")
B9: =IFERROR(INDEX(الموظفون_الاسم,MATCH($A9,الموظفون_الرقم,0)),"")
B10: =IFERROR(INDEX(الموظفون_الاسم,MATCH($A10,الموظفون_الرقم,0)),"")
B11: =IFERROR(INDEX(الموظفون_الاسم,MATCH($A11,الموظفون_الرقم,0)),"")
B12: =IFERROR(INDEX(الموظفون_الاسم,MATCH($A12,الموظفون_الرقم,0)),"")
B13: =IFERROR(INDEX(الموظفون_الاسم,MATCH($A13,الموظفون_الرقم,0)),"")
B14: =IFERROR(INDEX(الموظفون_الاسم,MATCH($A14,الموظفون_الرقم,0)),"")
... B502: =IFERROR(INDEX(الموظفون_الاسم,MATCH($A502,الموظفون_الرقم,0)),"")

Sheet تقييم الأداء
A1: تقييم الأداء — نموذج إدخال
A2: الرقم الوظيفي | B2: اسم الموظف | C2: فترة التقييم | D2: جودة العمل (100) | E2: الالتزام بالدوام (100) | F2: الإنتاجية (100) | G2: التعاون (100) | H2: تحقيق الأهداف (100) | I2: التقييم النهائي (100) | J2: التقدير | K2: ملاحظات المسؤول
B3: =IFERROR(INDEX(الموظفون_الاسم,MATCH($A3,الموظفون_الرقم,0)),"") | I3: =IF($A3="","",IF(COUNT($D3:$H3)=0,"",ROUND($D3*وزن_جودة_العمل+$E3*وزن_الالتزام+$F3*وزن_الإنتاجية+$G3*وزن_التعاون+$H3*وزن_الأهداف,1))) | J3: =IF($I3="","",IF($I3>=90,"ممتاز",IF($I3>=80,"جيد جدًا",IF($I3>=70,"جيد",IF($I3>=60,"مقبول","يحتاج تحسين")))))
B4: =IFERROR(INDEX(الموظفون_الاسم,MATCH($A4,الموظفون_الرقم,0)),"") | I4: =IF($A4="","",IF(COUNT($D4:$H4)=0,"",ROUND($D4*وزن_جودة_العمل+$E4*وزن_الالتزام+$F4*وزن_الإنتاجية+$G4*وزن_التعاون+$H4*وزن_الأهداف,1))) | J4: =IF($I4="","",IF($I4>=90,"ممتاز",IF($I4>=80,"جيد جدًا",IF($I4>=70,"جيد",IF($I4>=60,"مقبول","يحتاج تحسين")))))
B5: =IFERROR(INDEX(الموظفون_الاسم,MATCH($A5,الموظفون_الرقم,0)),"") | I5: =IF($A5="","",IF(COUNT($D5:$H5)=0,"",ROUND($D5*وزن_جودة_العمل+$E5*وزن_الالتزام+$F5*وزن_الإنتاجية+$G5*وزن_التعاون+$H5*وزن_الأهداف,1))) | J5: =IF($I5="","",IF($I5>=90,"ممتاز",IF($I5>=80,"جيد جدًا",IF($I5>=70,"جيد",IF($I5>=60,"مقبول","يحتاج تحسين")))))
B6: =IFERROR(INDEX(الموظفون_الاسم,MATCH($A6,الموظفون_الرقم,0)),"") | I6: =IF($A6="","",IF(COUNT($D6:$H6)=0,"",ROUND($D6*وزن_جودة_العمل+$E6*وزن_الالتزام+$F6*وزن_الإنتاجية+$G6*وزن_التعاون+$H6*وزن_الأهداف,1))) | J6: =IF($I6="","",IF($I6>=90,"ممتاز",IF($I6>=80,"جيد جدًا",IF($I6>=70,"جيد",IF($I6>=60,"مقبول","يحتاج تحسين")))))
B7: =IFERROR(INDEX(الموظفون_الاسم,MATCH($A7,الموظفون_الرقم,0)),"") | I7: =IF($A7="","",IF(COUNT($D7:$H7)=0,"",ROUND($D7*وزن_جودة_العمل+$E7*وزن_الالتزام+$F7*وزن_الإنتاجية+$G7*وزن_التعاون+$H7*وزن_الأهداف,1))) | J7: =IF($I7="","",IF($I7>=90,"ممتاز",IF($I7>=80,"جيد جدًا",IF($I7>=70,"جيد",IF($I7>=60,"مقبول","يحتاج تحسين")))))
B8: =IFERROR(INDEX(الموظفون_الاسم,MATCH($A8,الموظفون_الرقم,0)),"") | I8: =IF($A8="","",IF(COUNT($D8:$H8)=0,"",ROUND($D8*وزن_جودة_العمل+$E8*وزن_الالتزام+$F8*وزن_الإنتاجية+$G8*وزن_التعاون+$H8*وزن_الأهداف,1))) | J8: =IF($I8="","",IF($I8>=90,"ممتاز",IF($I8>=80,"جيد جدًا",IF($I8>=70,"جيد",IF($I8>=60,"مقبول","يحتاج تحسين")))))
B9: =IFERROR(INDEX(الموظفون_الاسم,MATCH($A9,الموظفون_الرقم,0)),"") | I9: =IF($A9="","",IF(COUNT($D9:$H9)=0,"",ROUND($D9*وزن_جودة_العمل+$E9*وزن_الالتزام+$F9*وزن_الإنتاجية+$G9*وزن_التعاون+$H9*وزن_الأهداف,1))) | J9: =IF($I9="","",IF($I9>=90,"ممتاز",IF($I9>=80,"جيد جدًا",IF($I9>=70,"جيد",IF($I9>=60,"مقبول","يحتاج تحسين")))))
B10: =IFERROR(INDEX(الموظفون_الاسم,MATCH($A10,الموظفون_الرقم,0)),"") | I10: =IF($A10="","",IF(COUNT($D10:$H10)=0,"",ROUND($D10*وزن_جودة_العمل+$E10*وزن_الالتزام+$F10*وزن_الإنتاجية+$G10*وزن_التعاون+$H10*وزن_الأهداف,1))) | J10: =IF($I10="","",IF($I10>=90,"ممتاز",IF($I10>=80,"جيد جدًا",IF($I10>=70,"جيد",IF($I10>=60,"مقبول","يحتاج تحسين")))))
B11: =IFERROR(INDEX(الموظفون_الاسم,MATCH($A11,الموظفون_الرقم,0)),"") | I11: =IF($A11="","",IF(COUNT($D11:$H11)=0,"",ROUND($D11*وزن_جودة_العمل+$E11*وزن_الالتزام+$F11*وزن_الإنتاجية+$G11*وزن_التعاون+$H11*وزن_الأهداف,1))) | J11: =IF($I11="","",IF($I11>=90,"ممتاز",IF($I11>=80,"جيد جدًا",IF($I11>=70,"جيد",IF($I11>=60,"مقبول","يحتاج تحسين")))))
B12: =IFERROR(INDEX(الموظفون_الاسم,MATCH($A12,الموظفون_الرقم,0)),"") | I12: =IF($A12="","",IF(COUNT($D12:$H12)=0,"",ROUND($D12*وزن_جودة_العمل+$E12*وزن_الالتزام+$F12*وزن_الإنتاجية+$G12*وزن_التعاون+$H12*وزن_الأهداف,1))) | J12: =IF($I12="","",IF($I12>=90,"ممتاز",IF($I12>=80,"جيد جدًا",IF($I12>=70,"جيد",IF($I12>=60,"مقبول","يحتاج تحسين")))))
B13: =IFERROR(INDEX(الموظفون_الاسم,MATCH($A13,الموظفون_الرقم,0)),"") | I13: =IF($A13="","",IF(COUNT($D13:$H13)=0,"",ROUND($D13*وزن_جودة_العمل+$E13*وزن_الالتزام+$F13*وزن_الإنتاجية+$G13*وزن_التعاون+$H13*وزن_الأهداف,1))) | J13: =IF($I13="","",IF($I13>=90,"ممتاز",IF($I13>=80,"جيد جدًا",IF($I13>=70,"جيد",IF($I13>=60,"مقبول","يحتاج تحسين")))))
B14: =IFERROR(INDEX(الموظفون_الاسم,MATCH($A14,الموظفون_الرقم,0)),"") | I14: =IF($A14="","",IF(COUNT($D14:$H14)=0,"",ROUND($D14*وزن_جودة_العمل+$E14*وزن_الالتزام+$F14*وزن_الإنتاجية+$G14*وزن_التعاون+$H14*وزن_الأهداف,1))) | J14: =IF($I14="","",IF($I14>=90,"ممتاز",IF($I14>=80,"جيد جدًا",IF($I14>=70,"جيد",IF($I14>=60,"مقبول","يحتاج تحسين")))))
... B502: =IFERROR(INDEX(الموظفون_الاسم,MATCH($A502,الموظفون_الرقم,0)),"") | I502: =IF($A502="","",IF(COUNT($D502:$H502)=0,"",ROUND($D502*وزن_جودة_العمل+$E502*وزن_الالتزام+$F502*وزن_الإنتاجية+$G502*وزن_التعاون+$H502*وزن_الأهداف,1))) | J502: =IF($I502="","",IF($I502>=90,"ممتاز",IF($I502>=80,"جيد جدًا",IF($I502>=70,"جيد",IF($I502>=60,"مقبول","يحتاج تحسين")))))

Sheet الجزاءات والمكافآت
A1: الجزاءات والمكافآت — نموذج إدخال
A2: الرقم الوظيفي | B2: اسم الموظف | C2: نوع القرار | D2: تصنيف القرار | E2: تاريخ القرار | F2: سبب القرار | G2: الجهة المعتمدة | H2: الأثر المالي | I2: تاريخ التنفيذ | J2: حالة التنفيذ | K2: الملاحظات
B3: =IFERROR(INDEX(الموظفون_الاسم,MATCH($A3,الموظفون_الرقم,0)),"")
B4: =IFERROR(INDEX(الموظفون_الاسم,MATCH($A4,الموظفون_الرقم,0)),"")
B5: =IFERROR(INDEX(الموظفون_الاسم,MATCH($A5,الموظفون_الرقم,0)),"")
B6: =IFERROR(INDEX(الموظفون_الاسم,MATCH($A6,الموظفون_الرقم,0)),"")
B7: =IFERROR(INDEX(الموظفون_الاسم,MATCH($A7,الموظفون_الرقم,0)),"")
B8: =IFERROR(INDEX(الموظفون_الاسم,MATCH($A8,الموظفون_الرقم,0)),"")
B9: =IFERROR(INDEX(الموظفون_الاسم,MATCH($A9,الموظفون_الرقم,0)),"")
B10: =IFERROR(INDEX(الموظفون_الاسم,MATCH($A10,الموظفون_الرقم,0)),"")
B11: =IFERROR(INDEX(الموظفون_الاسم,MATCH($A11,الموظفون_الرقم,0)),"")
B12: =IFERROR(INDEX(الموظفون_الاسم,MATCH($A12,الموظفون_الرقم,0)),"")
B13: =IFERROR(INDEX(الموظفون_الاسم,MATCH($A13,الموظفون_الرقم,0)),"")
B14: =IFERROR(INDEX(الموظفون_الاسم,MATCH($A14,الموظفون_الرقم,0)),"")
... B502: =IFERROR(INDEX(الموظفون_الاسم,MATCH($A502,الموظفون_الرقم,0)),"")

Sheet إنهاء الخدمة
A1: إنهاء الخدمة — نموذج إدخال
A2: الرقم الوظيفي | B2: اسم الموظف | C2: تاريخ تقديم الطلب | D2: نوع إنهاء الخدمة | E2: آخر يوم عمل | F2: سبب الإنهاء | G2: حالة إخلاء الطرف | H2: العهد الواجب تسليمها | I2: المستحقات النهائية | J2: حالة التسوية المالية | K2: حالة إغلاق الملف | L2: الملاحظات
B3: =IFERROR(INDEX(الموظفون_الاسم,MATCH($A3,الموظفون_الرقم,0)),"") | H3: =IF($A3="","",IF(COUNTIFS(العهد_الرقم,$A3,العهد_الحالة,"<>مسترجعة")>0,"⚠ يوجد عهد غير مسترجعة","لا عهد معلقة"))
B4: =IFERROR(INDEX(الموظفون_الاسم,MATCH($A4,الموظفون_الرقم,0)),"") | H4: =IF($A4="","",IF(COUNTIFS(العهد_الرقم,$A4,العهد_الحالة,"<>مسترجعة")>0,"⚠ يوجد عهد غير مسترجعة","لا عهد معلقة"))
B5: =IFERROR(INDEX(الموظفون_الاسم,MATCH($A5,الموظفون_الرقم,0)),"") | H5: =IF($A5="","",IF(COUNTIFS(العهد_الرقم,$A5,العهد_الحالة,"<>مسترجعة")>0,"⚠ يوجد عهد غير مسترجعة","لا عهد معلقة"))
B6: =IFERROR(INDEX(الموظفون_الاسم,MATCH($A6,الموظفون_الرقم,0)),"") | H6: =IF($A6="","",IF(COUNTIFS(العهد_الرقم,$A6,العهد_الحالة,"<>مسترجعة")>0,"⚠ يوجد عهد غير مسترجعة","لا عهد معلقة"))
B7: =IFERROR(INDEX(الموظفون_الاسم,MATCH($A7,الموظفون_الرقم,0)),"") | H7: =IF($A7="","",IF(COUNTIFS(العهد_الرقم,$A7,العهد_الحالة,"<>مسترجعة")>0,"⚠ يوجد عهد غير مسترجعة","لا عهد معلقة"))
B8: =IFERROR(INDEX(الموظفون_الاسم,MATCH($A8,الموظفون_الرقم,0)),"") | H8: =IF($A8="","",IF(COUNTIFS(العهد_الرقم,$A8,العهد_الحالة,"<>مسترجعة")>0,"⚠ يوجد عهد غير مسترجعة","لا عهد معلقة"))
B9: =IFERROR(INDEX(الموظفون_الاسم,MATCH($A9,الموظفون_الرقم,0)),"") | H9: =IF($A9="","",IF(COUNTIFS(العهد_الرقم,$A9,العهد_الحالة,"<>مسترجعة")>0,"⚠ يوجد عهد غير مسترجعة","لا عهد معلقة"))
B10: =IFERROR(INDEX(الموظفون_الاسم,MATCH($A10,الموظفون_الرقم,0)),"") | H10: =IF($A10="","",IF(COUNTIFS(العهد_الرقم,$A10,العهد_الحالة,"<>مسترجعة")>0,"⚠ يوجد عهد غير مسترجعة","لا عهد معلقة"))
B11: =IFERROR(INDEX(الموظفون_الاسم,MATCH($A11,الموظفون_الرقم,0)),"") | H11: =IF($A11="","",IF(COUNTIFS(العهد_الرقم,$A11,العهد_الحالة,"<>مسترجعة")>0,"⚠ يوجد عهد غير مسترجعة","لا عهد معلقة"))
B12: =IFERROR(INDEX(الموظفون_الاسم,MATCH($A12,الموظفون_الرقم,0)),"") | H12: =IF($A12="","",IF(COUNTIFS(العهد_الرقم,$A12,العهد_الحالة,"<>مسترجعة")>0,"⚠ يوجد عهد غير مسترجعة","لا عهد معلقة"))
B13: =IFERROR(INDEX(الموظفون_الاسم,MATCH($A13,الموظفون_الرقم,0)),"") | H13: =IF($A13="","",IF(COUNTIFS(العهد_الرقم,$A13,العهد_الحالة,"<>مسترجعة")>0,"⚠ يوجد عهد غير مسترجعة","لا عهد معلقة"))
B14: =IFERROR(INDEX(الموظفون_الاسم,MATCH($A14,الموظفون_الرقم,0)),"") | H14: =IF($A14="","",IF(COUNTIFS(العهد_الرقم,$A14,العهد_الحالة,"<>مسترجعة")>0,"⚠ يوجد عهد غير مسترجعة","لا عهد معلقة"))
... B502: =IFERROR(INDEX(الموظفون_الاسم,MATCH($A502,الموظفون_الرقم,0)),"") | H502: =IF($A502="","",IF(COUNTIFS(العهد_الرقم,$A502,العهد_الحالة,"<>مسترجعة")>0,"⚠ يوجد عهد غير مسترجعة","لا عهد معلقة"))

Sheet العهد
A1: العهد — نموذج إدخال
A2: رقم العهدة | B2: وصف الأصل | C2: الرقم التسلسلي | D2: الرقم الوظيفي | E2: اسم الموظف | F2: تاريخ التسليم | G2: الحالة عند التسليم | H2: تاريخ الإرجاع | I2: الحالة عند الإرجاع | J2: حالة العهدة | K2: الملاحظات
E3: =IFERROR(INDEX(الموظفون_الاسم,MATCH($D3,الموظفون_الرقم,0)),"")
E4: =IFERROR(INDEX(الموظفون_الاسم,MATCH($D4,الموظفون_الرقم,0)),"")
E5: =IFERROR(INDEX(الموظفون_الاسم,MATCH($D5,الموظفون_الرقم,0)),"")
E6: =IFERROR(INDEX(الموظفون_الاسم,MATCH($D6,الموظفون_الرقم,0)),"")
E7: =IFERROR(INDEX(الموظفون_الاسم,MATCH($D7,الموظفون_الرقم,0)),"")
E8: =IFERROR(INDEX(الموظفون_الاسم,MATCH($D8,الموظفون_الرقم,0)),"")
E9: =IFERROR(INDEX(الموظفون_الاسم,MATCH($D9,الموظفون_الرقم,0)),"")
E10: =IFERROR(INDEX(الموظفون_الاسم,MATCH($D10,الموظفون_الرقم,0)),"")
E11: =IFERROR(INDEX(الموظفون_الاسم,MATCH($D11,الموظفون_الرقم,0)),"")
E12: =IFERROR(INDEX(الموظفون_الاسم,MATCH($D12,الموظفون_الرقم,0)),"")
E13: =IFERROR(INDEX(الموظفون_الاسم,MATCH($D13,الموظفون_الرقم,0)),"")
E14: =IFERROR(INDEX(الموظفون_الاسم,MATCH($D14,الموظفون_الرقم,0)),"")
... E502: =IFERROR(INDEX(الموظفون_الاسم,MATCH($D502,الموظفون_الرقم,0)),"")

Sheet تقرير الموظفين
A1: =اسم_المؤسسة
A2: كشف بيانات الموظفين
A3: ="تاريخ إعداد التقرير: "&TEXT(TODAY(),"yyyy-mm-dd") | G3: ="السنة المالية: "&السنة_المالية
A6: الرقم الوظيفي | B6: الاسم الكامل | C6: المسمى الوظيفي | D6: الإدارة | E6: القسم | F6: نوع التوظيف | G6: تاريخ التعيين | H6: نهاية العقد | I6: الحالة الوظيفية | J6: الراتب الأساسي | K6: البدلات الثابتة | L6: إجمالي الراتب الأساسي والبدلات
A7: =IFERROR(INDEX('الموظفون'!$A$3:$A$502,1),"") | B7: =IFERROR(INDEX('الموظفون'!$B$3:$B$502,1),"") | C7: =IFERROR(INDEX('الموظفون'!$J$3:$J$502,1),"") | D7: =IFERROR(INDEX('الموظفون'!$K$3:$K$502,1),"") | E7: =IFERROR(INDEX('الموظفون'!$L$3:$L$502,1),"") | F7: =IFERROR(INDEX('الموظفون'!$N$3:$N$502,1),"") | G7: =IFERROR(INDEX('الموظفون'!$O$3:$O$502,1),"") | H7: =IFERROR(INDEX('الموظفون'!$Q$3:$Q$502,1),"") | I7: =IFERROR(INDEX('الموظفون'!$R$3:$R$502,1),"") | J7: =IFERROR(INDEX('الموظفون'!$S$3:$S$502,1),"") | K7: =IFERROR(INDEX('الموظفون'!$T$3:$T$502,1),"") | L7: =IFERROR(IF(INDEX(الموظفون_الرقم,1)="","",INDEX(الموظفون_الاساسي,1)+INDEX(الموظفون_البدلات,1)),"")
A8: =IFERROR(INDEX('الموظفون'!$A$3:$A$502,2),"") | B8: =IFERROR(INDEX('الموظفون'!$B$3:$B$502,2),"") | C8: =IFERROR(INDEX('الموظفون'!$J$3:$J$502,2),"") | D8: =IFERROR(INDEX('الموظفون'!$K$3:$K$502,2),"") | E8: =IFERROR(INDEX('الموظفون'!$L$3:$L$502,2),"") | F8: =IFERROR(INDEX('الموظفون'!$N$3:$N$502,2),"") | G8: =IFERROR(INDEX('الموظفون'!$O$3:$O$502,2),"") | H8: =IFERROR(INDEX('الموظفون'!$Q$3:$Q$502,2),"") | I8: =IFERROR(INDEX('الموظفون'!$R$3:$R$502,2),"") | J8: =IFERROR(INDEX('الموظفون'!$S$3:$S$502,2),"") | K8: =IFERROR(INDEX('الموظفون'!$T$3:$T$502,2),"") | L8: =IFERROR(IF(INDEX(الموظفون_الرقم,2)="","",INDEX(الموظفون_الاساسي,2)+INDEX(الموظفون_البدلات,2)),"")
A9: =IFERROR(INDEX('الموظفون'!$A$3:$A$502,3),"") | B9: =IFERROR(INDEX('الموظفون'!$B$3:$B$502,3),"") | C9: =IFERROR(INDEX('الموظفون'!$J$3:$J$502,3),"") | D9: =IFERROR(INDEX('الموظفون'!$K$3:$K$502,3),"") | E9: =IFERROR(INDEX('الموظفون'!$L$3:$L$502,3),"") | F9: =IFERROR(INDEX('الموظفون'!$N$3:$N$502,3),"") | G9: =IFERROR(INDEX('الموظفون'!$O$3:$O$502,3),"") | H9: =IFERROR(INDEX('الموظفون'!$Q$3:$Q$502,3),"") | I9: =IFERROR(INDEX('الموظفون'!$R$3:$R$502,3),"") | J9: =IFERROR(INDEX('الموظفون'!$S$3:$S$502,3),"") | K9: =IFERROR(INDEX('الموظفون'!$T$3:$T$502,3),"") | L9: =IFERROR(IF(INDEX(الموظفون_الرقم,3)="","",INDEX(الموظفون_الاساسي,3)+INDEX(الموظفون_البدلات,3)),"")
